Workbook
Name \0: #REF!
Name \0: #REF!
Name \01: #REF!
Name \01: #REF!
Name \a: #REF!
Name \a: #REF!
Name \b: #REF!
Name \c: #REF!
Name \d: #REF!
Name \e: #REF!
Name \f: #REF!
Name \f: #N/A
Name \g: #REF!
Name \g: #N/A
Name \h: #REF!
Name \h: #N/A
Name \i: #REF!
Name \j: #N/A
Name \k: #REF!
Name \m: #N/A
Name \n: #REF!
Name \o: #REF!
Name \p: #REF!
Name \Q: #REF!
Name \r: #N/A
Name \s: #REF!
Name \s: #N/A
Name \t: #N/A
Name \u: #REF!
Name \u: #N/A
Name \v: #N/A
Name \w: #N/A
Name \x: #REF!
Name \x: #N/A
Name \y: #REF!
Name \Z: #REF!
Name \z1: #REF!
Name ___________ADD1: #REF!
Name ___________ADD1: #REF!
Name ___________add12: #REF!
Name ___________add12: #REF!
Name ___________ADD2: #REF!
Name ___________ADD2: #REF!
Name ___________PP2: #REF!
Name ___________PP2: #REF!
Name __________ADD1: #REF!
Name __________ADD1: #REF!
Name __________add12: #REF!
Name __________add12: #REF!
Name __________ADD2: #REF!
Name __________ADD2: #REF!
Name __________PP2: #REF!
Name __________PP2: #REF!
Name _________ADD1: #REF!
Name _________ADD1: #REF!
Name _________add12: #REF!
Name _________add12: #REF!
Name _________ADD2: #REF!
Name _________ADD2: #REF!
Name _________PP1: #REF!

Sheet Programacion
H2: REGISTRO DE AVANCE Y PROGRAMACIÓN DIARIO DE OBRA PROYECTO LINEA DE TRANSMISION A 230kV San Felipe - Puerta de Oro | T2: NO. EDICIÓN: 4 FECHA DE EDICIÓN 1/02/2023
AC4: .
B7: EDICIÓN: 2 EDICIÓN: 3 EDICIÓN: 4 | H7: FECHA DEL CAMBIO: 26/10/2021 FECHA DEL CAMBIO: 29/10/2021 FECHA DEL CAMBIO: 1/02/2023 | T7: ASUNTO DEL CAMBIO: Se modifica el encabezado y se integra dentro del SGI. ASUNTO DEL CAMBIO: Se incluye el espacio para las observaciones por parte de control de obra. ASUNTO DEL CAMBIO: Se incluye espacio para reporte de instalación de puentes y entrega al CTE
B9: DESCRIPCIÓN DE EJECUTADO | M9: =TEXT(O9,"dddd") -> domingo | O9: 46054 | R9: DESCRIPCIÓN PROGRAMADO | U9: =TEXT(Z9,"dddd") -> lunes | Z9: =O9+1 -> 46055
B11: 1. SUMINISTROS | AA11: OBSERVACIONES CONTROL DE OBRA
B12: ÍTEM | C12: ACTIVIDAD | H12: ACUMULADO | J12: DESCRIPCIÓN DE EJECUTADO | R12: DESCRIPCIÓN PROGRAMADO
B13: 1.1 | C13: Recepción de Stub | H13: 1
B14: 1.2 | C14: Recepción de Estructura | H14: =(64/64)*100% -> 1 | R14: OB. COMPLEMENTARIAS
B15: 1.3 | C15: Recepción de cable Conductor y herrajes | H15: 1
B16: 1.4 | C16: Recepción de cable OPGW | H16: 1
B17: 1.5 | C17: Recepción y despacho de materiales | H17: =+SUM('Seg Diario'!HS13:HS76)/64 -> 1
B19: 2. PRELIMINARES | AA19: OBSERVACIONES CONTROL DE OBRA
B20: ÍTEM | C20: ACTIVIDAD | H20: ACUMULADO | J20: DESCRIPCIÓN DE EJECUTADO | O20: =O9 -> 46054 | R20: DESCRIPCIÓN PROGRAMADO | U20: =Z9 -> 46055 | V20: OBSERVACIONES | AB20: EJECUTADO | AC20: PROGRMADO
B21: 2.1 | C21: LIBERACIÓN PREDIAL CLIENTE PDO | H21: ='SOCIO-PREDIAL'!V71 -> 1
B22: 2.2 | C22: ACTA DE VECINDAD CLIENTE PDO | H22: ='SOCIO-PREDIAL'!N71 -> 1
B23: 2.3 | C23: LIBERACION PARA CONSTRUCCION - CLIENTE PDO | H23: ='SOCIO-PREDIAL'!Z71 -> 1
B24: 2.4 | C24: REPLANTEO TOPOGRÁFICO | H24: ='Seg Diario'!BB79 -> 1
B25: 2.5 | C25: PROBLEMAS TÉCNICOS
B26: 2.6 | C26: AHUYENTAMIENTO / FLORA / FAUNA | H26: ='Seg Diario'!PA79 -> 1
B27: 2.7 | C27: APROVECHAMIENTO FORESTAL SITIO DE TORRE | H27: ='Seg Diario'!PD79 -> 1
B28: 2.8 | C28: ARQUEOLOGIA | H28: ='Seg Diario'!PJ79 -> 1
B29: 2.9 | C29: APROVECHAMIENTO FORESTAL VANO | H29: ='SOCIO-AMBIENTAL'!Y71 -> 1
B30: 2.1 | C30: ADECUACIÓN ACCESOS | H30: ='SOCIO-AMBIENTAL'!S71 -> 0
B31: 2.11 | C31: ADECUACIONES PATIO | H31: 1
B32: 2.12 | C32: MARCACIÓN | H32: ='Seg Diario'!BF79 -> 1
B35: 3. OBRA CIVIL | AA35: OBSERVACIONES CONTROL DE OBRA
B36: No TORRE | C36: TIPO | D36: CIMENTACIÓN | E36: MARCACIÓN | F36: APROVECHAMIENTO FORESTAL | G36: PATA | H36: EXCAVACIÓN | I36: SOLADO | J36: PILOTES HELICOIDALES | K36: ACERO REFUERZO y/o ARMADO PARRILLA | L36: NIVELACIÓN | M36: VACIADO | N36: SPT BASE | O36: COMPACTACIÓN | P36: SPT MÓDULOS | Q36: OBRA COMPLEMENTARIA | R36: OBSERVACIONES EJECUTADO | V36: DESCRIPCIÓN PROGRAMADO | Z36: =+U20 -> 46055 | AB36: EJECUTADO | AC36: PROGRAMADO
A38: T001 | B38: T1 | C38: D6 | D38: HELICOIDAL | E38: ='Seg Diario'!BF12 -> 0 | F38: ='Seg Diario'!PD12 -> 0 | G38: A | H38: =VLOOKUP($A38,'Seg Diario'!$B$12:$HJ$76,64,FALSE) -> 1 | I38: =VLOOKUP($A38,'Seg Diario'!$B$12:$HJ$76,79,FALSE) -> 1 | J38: =VLOOKUP($A38,'Seg Diario'!$B$12:$HJ$76,94,FALSE) -> 1 | K38: =VLOOKUP($A38,'Seg Diario'!$B$12:$HJ$76,109,FALSE) -> 1 | L38: =VLOOKUP($A38,'Seg Diario'!$B$12:$HJ$76,124,FALSE) -> 1 | M38: =VLOOKUP($A38,'Seg Diario'!$B$12:$HJ$76,139,FALSE) -> 1 | N38: =VLOOKUP($A38,'Seg Diario'!$B$12:$HJ$76,184,FALSE) -> 1 | O38: =VLOOKUP($A38,'Seg Diario'!$B$12:$HJ$76,169,FALSE) -> 1 | P38: =VLOOKUP($A38,'Seg Diario'!$B$12:$HJ$76,204,FALSE) -> 1 | AC38: CRUZ
A39: T001 | G39: B | H39: =VLOOKUP($A38,'Seg Diario'!$B$12:$HJ$76,67,FALSE) -> 1 | I39: =VLOOKUP($A39,'Seg Diario'!$B$12:$HJ$76,82,FALSE) -> 1 | J39: =VLOOKUP($A39,'Seg Diario'!$B$12:$HJ$76,97,FALSE) -> 1 | K39: =VLOOKUP($A39,'Seg Diario'!$B$12:$HJ$76,112,FALSE) -> 1 | L39: =VLOOKUP($A39,'Seg Diario'!$B$12:$HJ$76,127,FALSE) -> 1 | M39: =VLOOKUP($A39,'Seg Diario'!$B$12:$HJ$76,142,FALSE) -> 1 | N39: =VLOOKUP($A39,'Seg Diario'!$B$12:$HJ$76,187,FALSE) -> 1 | O39: =VLOOKUP($A39,'Seg Diario'!$B$12:$HJ$76,172,FALSE) -> 1 | P39: =VLOOKUP($A39,'Seg Diario'!$B$12:$HJ$76,207,FALSE) -> 1
A40: T001 | G40: C | H40: =VLOOKUP($A38,'Seg Diario'!$B$12:$HJ$76,70,FALSE) -> 1 | I40: =VLOOKUP($A40,'Seg Diario'!$B$12:$HJ$76,85,FALSE) -> 1 | J40: =VLOOKUP($A40,'Seg Diario'!$B$12:$HJ$76,100,FALSE) -> 1 | K40: =VLOOKUP($A40,'Seg Diario'!$B$12:$HJ$76,115,FALSE) -> 1 | L40: =VLOOKUP($A40,'Seg Diario'!$B$12:$HJ$76,130,FALSE) -> 1 | M40: =VLOOKUP($A40,'Seg Diario'!$B$12:$HJ$76,145,FALSE) -> 1 | N40: =VLOOKUP($A40,'Seg Diario'!$B$12:$HJ$76,190,FALSE) -> 1 | O40: =VLOOKUP($A40,'Seg Diario'!$B$12:$HJ$76,175,FALSE) -> 1 | P40: =VLOOKUP($A40,'Seg Diario'!$B$12:$HJ$76,210,FALSE) -> 1
A41: T001 | G41: D | H41: =VLOOKUP($A38,'Seg Diario'!$B$12:$HJ$76,73,FALSE) -> 1 | I41: =VLOOKUP($A41,'Seg Diario'!$B$12:$HJ$76,88,FALSE) -> 1 | J41: =VLOOKUP($A41,'Seg Diario'!$B$12:$HJ$76,103,FALSE) -> 1 | K41: =VLOOKUP($A41,'Seg Diario'!$B$12:$HJ$76,118,FALSE) -> 1 | L41: =VLOOKUP($A41,'Seg Diario'!$B$12:$HJ$76,133,FALSE) -> 1 | M41: =VLOOKUP($A41,'Seg Diario'!$B$12:$HJ$76,148,FALSE) -> 1 | N41: =VLOOKUP($A41,'Seg Diario'!$B$12:$HJ$76,193,FALSE) -> 1 | O41: =VLOOKUP($A41,'Seg Diario'!$B$12:$HJ$76,178,FALSE) -> 1 | P41: =VLOOKUP($A41,'Seg Diario'!$B$12:$HJ$76,213,FALSE) -> 1
A42: T002 | B42: T2 | C42: B4 | D42: HELICOIDAL | E42: ='Seg Diario'!BF13 -> 1 | F42: ='Seg Diario'!PD13 -> 0 | G42: A | H42: =VLOOKUP($A42,'Seg Diario'!$B$12:$HJ$76,64,FALSE) -> 1 | I42: =VLOOKUP($A42,'Seg Diario'!$B$12:$HJ$76,79,FALSE) -> 1 | J42: =VLOOKUP($A42,'Seg Diario'!$B$12:$HJ$76,94,FALSE) -> 0 | K42: =VLOOKUP($A42,'Seg Diario'!$B$12:$HJ$76,109,FALSE) -> 1 | L42: =VLOOKUP($A42,'Seg Diario'!$B$12:$HJ$76,124,FALSE) -> 1 | M42: =VLOOKUP($A42,'Seg Diario'!$B$12:$HJ$76,139,FALSE) -> 1 | N42: =VLOOKUP($A42,'Seg Diario'!$B$12:$HJ$76,184,FALSE) -> 1 | O42: =VLOOKUP($A42,'Seg Diario'!$B$12:$HJ$76,169,FALSE) -> 1 | P42: =VLOOKUP($A42,'Seg Diario'!$B$12:$HJ$76,204,FALSE) -> 1 | AC42: WILSON
A43: T002 | G43: B | H43: =VLOOKUP($A42,'Seg Diario'!$B$12:$HJ$76,67,FALSE) -> 1 | I43: =VLOOKUP($A43,'Seg Diario'!$B$12:$HJ$76,82,FALSE) -> 1 | J43: =VLOOKUP($A43,'Seg Diario'!$B$12:$HJ$76,97,FALSE) -> 0 | K43: =VLOOKUP($A43,'Seg Diario'!$B$12:$HJ$76,112,FALSE) -> 1 | L43: =VLOOKUP($A43,'Seg Diario'!$B$12:$HJ$76,127,FALSE) -> 1 | M43: =VLOOKUP($A43,'Seg Diario'!$B$12:$HJ$76,142,FALSE) -> 1 | N43: =VLOOKUP($A43,'Seg Diario'!$B$12:$HJ$76,187,FALSE) -> 1 | O43: =VLOOKUP($A43,'Seg Diario'!$B$12:$HJ$76,172,FALSE) -> 1 | P43: =VLOOKUP($A43,'Seg Diario'!$B$12:$HJ$76,207,FALSE) -> 1
A44: T002 | G44: C | H44: =VLOOKUP($A42,'Seg Diario'!$B$12:$HJ$76,70,FALSE) -> 1 | I44: =VLOOKUP($A44,'Seg Diario'!$B$12:$HJ$76,85,FALSE) -> 1 | J44: =VLOOKUP($A44,'Seg Diario'!$B$12:$HJ$76,100,FALSE) -> 0 | K44: =VLOOKUP($A44,'Seg Diario'!$B$12:$HJ$76,115,FALSE) -> 1 | L44: =VLOOKUP($A44,'Seg Diario'!$B$12:$HJ$76,130,FALSE) -> 1 | M44: =VLOOKUP($A44,'Seg Diario'!$B$12:$HJ$76,145,FALSE) -> 1 | N44: =VLOOKUP($A44,'Seg Diario'!$B$12:$HJ$76,190,FALSE) -> 1 | O44: =VLOOKUP($A44,'Seg Diario'!$B$12:$HJ$76,175,FALSE) -> 1 | P44: =VLOOKUP($A44,'Seg Diario'!$B$12:$HJ$76,210,FALSE) -> 1
A45: T002 | G45: D | H45: =VLOOKUP($A42,'Seg Diario'!$B$12:$HJ$76,73,FALSE) -> 1 | I45: =VLOOKUP($A45,'Seg Diario'!$B$12:$HJ$76,88,FALSE) -> 1 | J45: =VLOOKUP($A45,'Seg Diario'!$B$12:$HJ$76,103,FALSE) -> 0 | K45: =VLOOKUP($A45,'Seg Diario'!$B$12:$HJ$76,118,FALSE) -> 1 | L45: =VLOOKUP($A45,'Seg Diario'!$B$12:$HJ$76,133,FALSE) -> 1 | M45: =VLOOKUP($A45,'Seg Diario'!$B$12:$HJ$76,148,FALSE) -> 1 | N45: =VLOOKUP($A45,'Seg Diario'!$B$12:$HJ$76,193,FALSE) -> 1 | O45: =VLOOKUP($A45,'Seg Diario'!$B$12:$HJ$76,178,FALSE) -> 1 | P45: =VLOOKUP($A45,'Seg Diario'!$B$12:$HJ$76,213,FALSE) -> 1
A46: T003 | B46: T3 | C46: B4 | D46: HELICOIDAL | E46: ='Seg Diario'!BF14 -> 1 | F46: ='Seg Diario'!PD14 -> 0 | G46: A | H46: =VLOOKUP($A46,'Seg Diario'!$B$12:$HJ$76,64,FALSE) -> 1 | I46: =VLOOKUP($A46,'Seg Diario'!$B$12:$HJ$76,79,FALSE) -> 1 | J46: =VLOOKUP($A46,'Seg Diario'!$B$12:$HJ$76,94,FALSE) -> 1 | K46: =VLOOKUP($A46,'Seg Diario'!$B$12:$HJ$76,109,FALSE) -> 1 | L46: =VLOOKUP($A46,'Seg Diario'!$B$12:$HJ$76,124,FALSE) -> 1 | M46: =VLOOKUP($A46,'Seg Diario'!$B$12:$HJ$76,139,FALSE) -> 1 | N46: =VLOOKUP($A46,'Seg Diario'!$B$12:$HJ$76,184,FALSE) -> 1 | O46: =VLOOKUP($A46,'Seg Diario'!$B$12:$HJ$76,169,FALSE) -> 1 | P46: =VLOOKUP($A46,'Seg Diario'!$B$12:$HJ$76,204,FALSE) -> 1 | AC46: ANGEL
A47: T003 | G47: B | H47: =VLOOKUP($A46,'Seg Diario'!$B$12:$HJ$76,67,FALSE) -> 1 | I47: =VLOOKUP($A47,'Seg Diario'!$B$12:$HJ$76,82,FALSE) -> 1 | J47: =VLOOKUP($A47,'Seg Diario'!$B$12:$HJ$76,97,FALSE) -> 1 | K47: =VLOOKUP($A47,'Seg Diario'!$B$12:$HJ$76,112,FALSE) -> 1 | L47: =VLOOKUP($A47,'Seg Diario'!$B$12:$HJ$76,127,FALSE) -> 1 | M47: =VLOOKUP($A47,'Seg Diario'!$B$12:$HJ$76,142,FALSE) -> 1 | N47: =VLOOKUP($A47,'Seg Diario'!$B$12:$HJ$76,187,FALSE) -> 1 | O47: =VLOOKUP($A47,'Seg Diario'!$B$12:$HJ$76,172,FALSE) -> 1 | P47: =VLOOKUP($A47,'Seg Diario'!$B$12:$HJ$76,207,FALSE) -> 1
A48: T003 | G48: C | H48: =VLOOKUP($A46,'Seg Diario'!$B$12:$HJ$76,70,FALSE) -> 1 | I48: =VLOOKUP($A48,'Seg Diario'!$B$12:$HJ$76,85,FALSE) -> 1 | J48: =VLOOKUP($A48,'Seg Diario'!$B$12:$HJ$76,100,FALSE) -> 1 | K48: =VLOOKUP($A48,'Seg Diario'!$B$12:$HJ$76,115,FALSE) -> 1 | L48: =VLOOKUP($A48,'Seg Diario'!$B$12:$HJ$76,130,FALSE) -> 1 | M48: =VLOOKUP($A48,'Seg Diario'!$B$12:$HJ$76,145,FALSE) -> 1 | N48: =VLOOKUP($A48,'Seg Diario'!$B$12:$HJ$76,190,FALSE) -> 1 | O48: =VLOOKUP($A48,'Seg Diario'!$B$12:$HJ$76,175,FALSE) -> 1 | P48: =VLOOKUP($A48,'Seg Diario'!$B$12:$HJ$76,210,FALSE) -> 1
A49: T003 | G49: D | H49: =VLOOKUP($A46,'Seg Diario'!$B$12:$HJ$76,73,FALSE) -> 1 | I49: =VLOOKUP($A49,'Seg Diario'!$B$12:$HJ$76,88,FALSE) -> 1 | J49: =VLOOKUP($A49,'Seg Diario'!$B$12:$HJ$76,103,FALSE) -> 1 | K49: =VLOOKUP($A49,'Seg Diario'!$B$12:$HJ$76,118,FALSE) -> 1 | L49: =VLOOKUP($A49,'Seg Diario'!$B$12:$HJ$76,133,FALSE) -> 1 | M49: =VLOOKUP($A49,'Seg Diario'!$B$12:$HJ$76,148,FALSE) -> 1 | N49: =VLOOKUP($A49,'Seg Diario'!$B$12:$HJ$76,193,FALSE) -> 1 | O49: =VLOOKUP($A49,'Seg Diario'!$B$12:$HJ$76,178,FALSE) -> 1 | P49: =VLOOKUP($A49,'Seg Diario'!$B$12:$HJ$76,213,FALSE) -> 1
A50: T004 | B50: T4 | C50: D4 | D50: HELICOIDAL | E50: ='Seg Diario'!BF15 -> 1 | F50: ='Seg Diario'!PD15 -> 0 | G50: A | H50: =VLOOKUP($A50,'Seg Diario'!$B$12:$HJ$76,64,FALSE) -> 1 | I50: =VLOOKUP($A50,'Seg Diario'!$B$12:$HJ$76,79,FALSE) -> 1 | J50: =VLOOKUP($A50,'Seg Diario'!$B$12:$HJ$76,94,FALSE) -> 1 | K50: =VLOOKUP($A50,'Seg Diario'!$B$12:$HJ$76,109,FALSE) -> 1 | L50: =VLOOKUP($A50,'Seg Diario'!$B$12:$HJ$76,124,FALSE) -> 1 | M50: =VLOOKUP($A50,'Seg Diario'!$B$12:$HJ$76,139,FALSE) -> 1 | N50: =VLOOKUP($A50,'Seg Diario'!$B$12:$HJ$76,184,FALSE) -> 1 | O50: =VLOOKUP($A50,'Seg Diario'!$B$12:$HJ$76,169,FALSE) -> 1 | P50: =VLOOKUP($A50,'Seg Diario'!$B$12:$HJ$76,204,FALSE) -> 1 | Q50: ='Seg Diario'!NI16 -> 1 | AC50: MECT
...

Sheet Seg Diario
B1: 1 | C1: 2 | D1: 3 | E1: 4 | F1: 5 | G1: 6 | H1: 7 | I1: 8 | J1: 9 | K1: 10 | L1: 11 | M1: 12 | N1: 13 | O1: 14 | P1: 15 | Q1: 16 | R1: 17 | S1: 18 | T1: 19 | U1: 20 | V1: 21 | W1: 22 | X1: 23 | Y1: 24 | Z1: 25 | AA1: 26 | AB1: 27 | AC1: 28 | AD1: 29 | AE1: 30 | AF1: 31 | AG1: 32 | AH1: 33 | AI1: 34 | AJ1: 35 | AK1: 36 | AL1: 37 | AM1: 38 | AN1: 39 | AO1: 40 | AP1: 41 | AQ1: 42 | AR1: 43 | AS1: 44 | AT1: 45 | AU1: 46 | AV1: 47 | AW1: 48 | AX1: 49 | AY1: 50 | AZ1: 51 | BA1: 52 | BB1: 53 | BC1: 54 | BD1: 55 | BE1: 56 | BF1: 57 | BG1: 58 | BH1: 59 | BI1: 60 | BJ1: 61 | BK1: 62 | BL1: 63 | BM1: 64 | BN1: 65 | BO1: 66 | BP1: 67 | BQ1: 68 | BR1: 69 | BS1: 70 | BT1: 71 | BU1: 72 | BV1: 73 | BW1: 74 | BX1: 75 | BY1: 76 | BZ1: 77 | CA1: 78 | CB1: 79 | CC1: 80 | CD1: 81 | CE1: 82 | CF1: 83 | CG1: 84 | CH1: 85 | CI1: 86 | CJ1: 87 | CK1: 88 | CL1: 89 | CM1: 90 | CN1: 91 | CO1: 92 | CP1: 93 | CQ1: 94 | CR1: 95 | CS1: 96 | CT1: 97 | CU1: 98 | CV1: 99 | CW1: 100 | CX1: 101 | CY1: 102 | CZ1: 103 | DA1: 104 | DB1: 105 | DC1: 106 | DD1: 107 | DE1: 108 | DF1: 109 | DG1: 110 | DH1: 111 | DI1: 112 | DJ1: 113 | DK1: 114 | DL1: 115 | DM1: 116 | DN1: 117 | DO1: 118 | DP1: 119 | DQ1: 120 | DR1: 121 | DS1: 122 | DT1: 123 | DU1: 124 | DV1: 125 | DW1: 126 | DX1: 127 | DY1: 128 | DZ1: 129 | EA1: 130 | EB1: 131 | EC1: 132 | ED1: 133 | EE1: 134 | EF1: 135 | EG1: 136 | EH1: 137 | EI1: 138 | EJ1: 139 | EK1: 140 | EL1: 141 | EM1: 142 | EN1: 143 | EO1: 144 | EP1: 145 | EQ1: 146 | ER1: 147 | ES1: 148 | ET1: 149 | EU1: 150 | EV1: 151 | EW1: 152 | EX1: 153 | EY1: 154 | EZ1: 155 | FA1: 156 | FB1: 157 | FC1: 158 | FD1: 159 | FE1: 160 | FF1: 161 | FG1: 162 | FH1: 163 | FI1: 164 | FJ1: 165 | FK1: 166 | FL1: 167 | FM1: 168 | FN1: 169 | FO1: 170 | FP1: 171 | FQ1: 172 | FR1: 173 | FS1: 174 | FT1: 175 | FU1: 176 | FV1: 177 | FW1: 178 | FX1: 179 | FY1: 180 | FZ1: 181 | GA1: 182 | GB1: 183 | GC1: 184 | GD1: 185 | GE1: 186 | GF1: 187 | GG1: 188 | GH1: 189 | GI1: 190 | GJ1: 191 | GK1: 192 | GL1: 193 | GM1: 194 | GN1: 195 | GO1: 196 | GP1: 197 | GQ1: 198 | GR1: 199 | GS1: 200 | GT1: 201 | GU1: 202 | GV1: 203 | GW1: 204 | GX1: 205 | GY1: 206 | GZ1: 207 | HA1: 208 | HB1: 209 | HC1: 210 | HD1: 211 | HE1: 212 | HF1: 213 | HG1: 214 | HH1: 215 | HI1: 216 | HJ1: 217 | HK1: 218 | HL1: 219 | HM1: 220 | HN1: 221 | HO1: 222 | HP1: 223 | HQ1: 224 | HR1: 225 | HS1: 226 | HT1: 227 | HU1: 228 | HV1: 229 | HW1: 230 | HX1: 231 | HY1: 232 | HZ1: 233 | IA1: 234 | IB1: 235 | IC1: 236 | ID1: 237 | IE1: 238 | IF1: 239 | IH1: 240 | II1: 241 | IJ1: 242 | IK1: 243 | IL1: 244 | IM1: 245 | IN1: =IM1+1 -> 246 | IO1: =IN1+1 -> 247 | IP1: =IO1+1 -> 248 | IQ1: =IP1+1 -> 249 | IR1: =IQ1+1 -> 250 | IS1: =IR1+1 -> 251 | IT1: =IS1+1 -> 252 | IU1: =IT1+1 -> 253 | ... KI1: =KH1+1 -> 293 | KJ1: =KE1+1 -> 290 | KK1: =KJ1+1 -> 291 | KL1: =KK1+1 -> 292 | KM1: =KL1+1 -> 293 | KN1: =KM1+1 -> 294 | KO1: =KN1+1 -> 295 | KP1: =KO1+1 -> 296 | KQ1: =KP1+1 -> 297 | KR1: =KQ1+1 -> 298 | ... NP1: =NO1+1 -> 374 | NQ1: =NL1+1 -> 371 | NR1: =NQ1+1 -> 372 | NS1: =NR1+1 -> 373 | NT1: =NS1+1 -> 374 | NU1: =NT1+1 -> 375 | NV1: =NU1+1 -> 376 | NW1: =NV1+1 -> 377 | NX1: =NW1+1 -> 378 | NY1: =NX1+1 -> 379 | ... PE1: =PD1+1 -> 411 | PF1: =PB1+1 -> 409 | PG1: =PF1+1 -> 410 | PH1: =PG1+1 -> 411 | PI1: =PE1+1 -> 412 | PJ1: =PI1+1 -> 413 | PK1: =PJ1+1 -> 414 | PL1: =PK1+1 -> 415 | PM1: =PL1+1 -> 416 | PN1: =PM1+1 -> 417 | PO1: =PK1+1 -> 415 | PP1: =PO1+1 -> 416 | PQ1: =PP1+1 -> 417 | PR1: =PQ1+1 -> 418 | PS1: =PR1+1 -> 419 | PT1: =PS1+1 -> 420 | PU1: =PT1+1 -> 421 | PV1: =PU1+1 -> 422 | PW1: =PV1+1 -> 423 | ... QJ1: =QI1+1 -> 436
B2: 859 | FM2: 168 | FN2: 169 | FO2: 170 | FP2: 171 | FQ2: 172 | FR2: 173 | FS2: 174 | FT2: 175 | FU2: 176 | FV2: 177 | FW2: 178 | FX2: 179 | FY2: 180 | FZ2: 181 | GA2: 182 | GB2: 183 | GC2: 184 | GD2: 185 | GE2: 186 | GF2: 187 | GG2: 188 | GH2: 189 | GI2: 190 | GJ2: 191 | GK2: 192 | GL2: 193 | GM2: 194 | GN2: 195 | GO2: 196 | GP2: 197 | GQ2: 1 | GR2: 199 | GS2: 200 | GT2: 201 | GU2: 202 | GV2: 203 | GW2: 204 | GX2: 205 | GY2: 206 | GZ2: 207 | HA2: 208 | HB2: 209 | HC2: 210 | HD2: 211 | HE2: 212 | HF2: 213 | HG2: 214 | HH2: 215 | HI2: 216 | HJ2: 217 | HK2: =COLUMN()-1 -> 218 | HL2: =COLUMN()-1 -> 219 | HM2: =COLUMN()-1 -> 220 | IN2: 1
G3: p
H4: =COLUMN()-1 -> 7 | EP4: VACIADO HORMIGON, HOMOLOGA EL ARMADO DE PARRILLA | FD4: NO APLICA PARA ZAPATA | HS4: =COLUMN() -> 227 | HT4: =COLUMN() -> 228 | HU4: =COLUMN() -> 229 | HV4: =COLUMN()-1 -> 229 | HW4: =COLUMN()-1 -> 230 | HX4: =COLUMN()-1 -> 231 | HY4: =COLUMN()-1 -> 232 | HZ4: =COLUMN()-1 -> 233 | IA4: =COLUMN()-1 -> 234 | IB4: =COLUMN()-1 -> 235 | IC4: =COLUMN()-1 -> 236 | ... QS4: =COLUMN()-1 -> 460
P5: LLENO | Q5: PR 5% | HK5: 0.3 | HL5: =COLUMN() -> 220 | HM5: =COLUMN() -> 221 | IN5: 0.2 | NB5: 0.252 | NP5: 0.04 | NX5: 0.01 | PD5: =COLUMN() -> 420 | PO5: 0.1 | QF5: 0.048 | QL5: =COLUMN()-1 -> 453 | QM5: =SUM(BE5:QJ5) -> 861.95
P6: RELLENO | Q6: Z 25% y PR 25%
B7: LT 230 kV SAN FELIPE - PUERTA DE ORO - INSTELEC SAS | BY7: 0.4 | CN7: 0.05 | DR7: 0.1 | EV7: 0.4 | FZ7: 0.05 | HV7: 0.1 | HY7: 0.2 | IB7: 0.45 | IE7: 0.25
B8: CONTRATISTA: INSTELEC SAS | AF8: Diseño Mezcla=> | AG8: 8 | AH8: 0.63 | AI8: 0.67 | AL8: Diseño Mezcla=> | AM8: 9 | AN8: 0.59 | AO8: 0.68 | AR8: Diseño Mezcla=> | AS8: 4 | AT8: 1.5 | AU8: 0 | BE8: OBRA CIVIL - CIMENTACIÓN | HR8: MONTAJE | IS8: TENDIDO | NH8: OBRAS DE PROTECCION | NM8: REVISION PRUEBAS GENERAL | NQ8: PUESTA EN SERVICIO-PES | NU8: INFORME FINAL | NY8: APROVECHAMIENTO TORRES | OB8: APROVECHAMIENTO VANO (ADELANTE) | OE8: ACCESORIOS (DESVIADORES Y BALIZAS) (VANO ADELANTE) | OH8: GESTION AMBIENTAL | PT8: REPLANTEO y ACCESO
B9: SEGUIMIENTO DIARIO DE OBRA | S9: Cantidades planillas y protocolos | Z9: Cantidades de almacen | BA9: REPLANTEO | BE9: MARCACIÓN | BG9: PLANILLA APROBADA | BI9: TRANSPORTE CIMENTACIONES | BL9: EXCAVACIÓN | CA9: SOLADO | CP9: INSTALACION DE PILOTES | DE9: ACERO DE REFUERZO | DT9: NIVELACION | EI9: VACIADO HORMIGON (CONCRETO) | EX9: LLENO | FM9: RELLENO | GB9: SISTEMA PUESTA A TIERRA (BASE) | GQ9: AVANCE CIMENTACIÓN | GV9: SPT - MODULOS | HK9: AVANCE OBRA CIVIL | HR9: MONTAJE | IN9: AVANCE MONTAJE | IS9: LONGITUD | IT9: TIRO | IU9: TRANSPORTE TENDIDO | IX9: TENDIDO DE CABLE CONDUCTOR | KT9: AVANCE CABLE CONDUCTOR | KX9: FIBRA OPTICA IZQUIERDA | LV9: AVANCE CABLE DE GUARDA FO | LZ9: FIBRA OPTICA DERECHA | MX9: AVANCE CABLE DE GUARDA CONVENCIONAL | NB9: AVANCE TENDIDO | NH9: OBRAS COMPLEMENTARIAS | NY9: OBRAS COMPLEMENTARIAS | OB9: OBRAS COMPLEMENTARIAS | OE9: OBRAS COMPLEMENTARIAS | OH9: GESTION AMBIENTAL | PO9: AVANCE GESTION AMBIENTAL | PT9: REPLANTEO y ACCESO | QF9: AVANCE REPLANTEO y ACCESO
B10: NUMERO | C10: TIRO TENDIDO | D10: TIPO CIMENTACION | E10: TIPO DE | F10: PESO ESTRUC. | G10: CUADRILLA | H10: CUADRILLA | I10: CUADRILLA | J10: (T F) TIPO DE FUNDACION - CONTRATO (INGENIERIA) | N10: TIPO ACCESO | O10: (T F) TIPO DE FUNDACION - CONSTRUIDA | S10: CIMENTACIONES | T10: Acero Kg | U10: Parrilla kg | V10: Concreto m3 | W10: Solado m3 | X10: Microp ml | Y10: Relleno m3 | Z10: Excav m3 | AA10: Acero Kg | AB10: Parrilla kg | AC10: Concreto 3000 psi m3 | AD10: Cemento Concreto 3000 psi | AE10: Arena Concreto 3000 psi | AF10: Grava Concreto 3000 psi | AG10: Cemento Equivalente Conc. 3000 psi | AH10: Arena Equivalente Conc. 3000 psi | AI10: Grava Equivalente Conc. 3000 psi | AJ10: Cemento Concreto 4000 psi | AK10: Arena Concreto 4000 psi | AL10: Grava Concreto 4000 psi | AM10: Cemento Equivalente Conc. 4000 psi | AN10: Arena Equivalente Conc. 4000 psi | AO10: Grava Equivalente Conc. 4000 psi | AP10: Cemento Concreto 1500 psi | AQ10: Arena Concreto 1500 psi | AR10: Grava Concreto 1500 psi | AS10: Cemento Equivalente Conc. 1500 psi | AT10: Arena Equivalente Conc. 1500 psi | AU10: Grava Equivalente Conc. 1500 psi | AV10: Barras MP | AW10: Liberación Arqueologica | AY10: Restricción para | AZ10: Observaciones | BA10: RESUMEN REPLANTEO | BC10: Acta No. | BD10: Fecha | BE10: TORRES | BG10: PARA EXCAVACIÓN | BI10: MATERIALES Y ESTRUCTURAS DE OBRA CIVIL | BL10: A | BO10: B | BR10: C | BU10: D | BX10: ="Total "&PROPER(BL9) -> Total Excavación | CA10: A | CD10: B | CG10: C | CJ10: D | CM10: ="Total "&PROPER(CA9) -> Total Solado | CP10: A | CS10: B | CV10: C | CY10: D | DB10: ="Total "&PROPER(CP9) -> Total Instalacion De Pilotes | DE10: A | DH10: B | DK10: C | DN10: D | DQ10: ="Total "&PROPER(DE9) -> Total Acero De Refuerzo | DT10: A | DW10: B | DZ10: C | EC10: D | EF10: ="Total "&PROPER(DT9) -> Total Nivelacion | EI10: A | EL10: B | EO10: C | ER10: D | EU10: ="Total "&PROPER(EI9) -> Total Vaciado Hormigon (Concreto) | EX10: A | FA10: B | FD10: C | FG10: D | FJ10: ="Total "&PROPER(EX9) -> Total Lleno | FM10: A | FP10: B | FS10: C | FV10: D | FY10: ="Total "&PROPER(FM9) -> Total Relleno | GB10: A | GE10: B | GH10: C | GK10: D | GN10: ="Total "&PROPER(GB9) -> Total Sistema Puesta A Tierra (Base) | GQ10: Porcentaje | GR10: Fecha | GS10: Fecha | GT10: Acta No. | GU10: Fecha | GV10: A | GY10: B | HB10: C | HE10: D | HH10: ="Total "&PROPER(GV9) -> Total Spt - Modulos | HK10: Porcentaje | HL10: Fecha | HM10: Fecha | HN10: Acta No. | HO10: Fecha | HP10: OK CONCRETO | HR10: SELECCIÓN | HU10: TRANSPORTE ESTRUCTURA | HX10: PREARMADO | IA10: ARMADO | ID10: REVISIÓN | IG10: Verticalidad y torsión | IH10: RECIBIDA x INSTELEC SUPERVISIÓN | IK10: ENTREGA a WSP | IN10: Porcentaje | IO10: Fecha | IP10: Fecha | IQ10: Acta No. | IR10: Fecha | IS10: LINEAL | IT10: NUMERO | IU10: TRANSPORTE PARA LOS TENDIDOS DE CONDUCTOR Y GUARDAS | IX10: TCC PROTECCIONES EN CRUCES | JA10: TCC VESTIDA | JD10: TCC RIEGA MANILA | JH10: TCC RIEGA GUAYA | JL10: TCC C1-FASE 1 | JP10: TCC C1-FASE 2 | JT10: TCC C1-FASE 3 | JX10: TCC C2-FASE 1 | KB10: TCC C2-FASE 2 | KF10: TCC C2-FASE 3 | KJ10: TCC INSTALACION DE PUENTES Y GRAPADO | KN10: TCC AMARRE-GRAPADO-REGULACIÓN | KQ10: TGFO REVISION y ENTREGA | KT10: Porcentaje | KU10: kilómetros | KV10: Fecha | KW10: Fecha | KX10: TGFO VESTIDA | LA10: TGFO RIEGA DE MANILA | LE10: TGFO RIEGA DE GUAYA | LI10: TGFO RIEGA DEL CABLE OPGW | LM10: TGFO AMARRE-GRAPADO-REGULACIÓN | LP10: TGFO INSTALACION ACCESORIOS | LS10: TGFO REVISION y ENTREGA | LV10: Porcentaje | LW10: kilómetros | LX10: Fecha | LY10: Fecha | LZ10: TGCONV VESTIDA | MC10: TGCONV RIEGA DE MANILA | MG10: TGCONV RIEGA DE GUAYA | MK10: TGCONV RIEGA DEL CABLE OPGW | MO10: TGCONV AMARRE-GRAPADO-REGULACIÓN | MR10: TGCONV INSTALACION ACCESORIOS | MU10: TGCONV REVISION y ENTREGA | MX10: Porcentaje | MY10: kilómetros | MZ10: Fecha | NA10: Fecha | NB10: Porcentaje | NC10: kilómetros | ND10: Fecha | NE10: Fecha | NF10: Acta No. | NG10: Fecha | NH10: Fecha | NI10: Porcentaje | NJ10: Fecha | NK10: Acta No. | NL10: Fecha | NM10: Porcentaje | NN10: kilómetros | NO10: Fecha | NP10: Fecha | NQ10: Porcentaje | NR10: kilómetros | NS10: Fecha | NT10: Fecha | NU10: Porcentaje | NV10: kilómetros | NW10: Fecha | NX10: Fecha | NY10: Fecha | NZ10: Porcentaje | OA10: Fecha | OB10: Fecha | OC10: Porcentaje | OD10: Fecha | OE10: Fecha | OF10: Porcentaje | OG10: Fecha | OH10: DEFINICION | OK10: EJECUCION | ON10: INVENTARIO | OQ10: VERIFICACION CUERPOS DE AGUA | OT10: PROSPECCION ARQUEOLOGICA | OW10: ADECUACION ACCESOS | OZ10: AHUYENTAMIENTO DE ESPECIES | PC10: APROVECHAMIENTO FORESTAL | PF10: APROVECHAMIENTO VANO ( + ) | PI10: MONITOREO ARQUEOLOGICO | PL10: MONITOREO CAMPO | PO10: Porcentaje | PP10: Fecha | PQ10: Fecha | PR10: Acta No. | PS10: Fecha | PT10: REPLANTEO DE SITIO TORRE | PW10: INFORME REPLANTEO | PZ10: PLAN DE ACCESO | QC10: APROBACION REPLANTEO y PLAN ACCESO | QF10: Porcentaje | QG10: Fecha | QH10: Fecha | QI10: Acta No. | QJ10: Fecha | QL10: AVANCE TENDIDO CONDUCTOR | QO10: PINTURA PATAS | QR10: MEDICION SPT
B11: TORRE | D11: TORRE | E11: TORRE | F11: TONELADAS | G11: OBRA CIVIL | H11: P: Pre M: MONTAJE | I11: TENDIDO | J11: A | K11: B | L11: C | M11: D | N11: TIPO | O11: A | P11: B | Q11: C | R11: D | AD11: bulto 50kg | AE11: m3 | AF11: m3 | AG11: m3 | AH11: m3 | AI11: m3 | AJ11: bulto 50kg | AK11: m3 | AL11: m3 | AM11: m3 | AN11: m3 | AO11: m3 | AP11: bulto 50kg | AQ11: m3 | AR11: m3 | AS11: m3 | AT11: m3 | AU11: m3 | AV11: ml | AW11: Monitoreo | AX11: Estado | AY11: Construcción | BA11: Fecha | BB11: Avance | BC11: Facturación | BD11: Acta | BE11: Fecha | BF11: Avance | BG11: Fecha | BH11: Avance | BI11: Fecha ini | BJ11: Avance | BK11: Fecha fin | BL11: Fecha ini | BM11: Avance | BN11: Fecha fin | BO11: Fecha ini | BP11: Avance | BQ11: Fecha fin | BR11: Fecha ini | BS11: Avance | BT11: Fecha fin | BU11: Fecha ini | BV11: Avance | BW11: Fecha fin | BX11: Fecha ini | BY11: Avance | BZ11: Fecha fin | CA11: Fecha ini | CB11: Avance | CC11: Fecha fin | CD11: Fecha ini | CE11: Avance | CF11: Fecha fin | CG11: Fecha ini | CH11: Avance | CI11: Fecha fin | CJ11: Fecha ini | CK11: Avance | CL11: Fecha fin | CM11: Fecha ini | CN11: Avance | CO11: Fecha fin | CP11: Fecha ini | CQ11: Avance | CR11: Fecha fin | CS11: Fecha ini | CT11: Avance | CU11: Fecha fin | CV11: Fecha ini | CW11: Avance | CX11: Fecha fin | CY11: Fecha ini | CZ11: Avance | DA11: Fecha fin | DB11: Fecha ini | DC11: Avance | DD11: Fecha fin | DE11: Fecha ini | DF11: Avance | DG11: Fecha fin | DH11: Fecha ini | DI11: Avance | DJ11: Fecha fin | DK11: Fecha ini | DL11: Avance | DM11: Fecha fin | DN11: Fecha ini | DO11: Avance | DP11: Fecha fin | DQ11: Fecha ini | DR11: Avance | DS11: Fecha fin | DT11: Fecha ini | DU11: Avance | DV11: Fecha fin | DW11: Fecha ini | DX11: Avance | DY11: Fecha fin | DZ11: Fecha ini | EA11: Avance | EB11: Fecha fin | EC11: Fecha ini | ED11: Avance | EE11: Fecha fin | EF11: Fecha ini | EG11: Avance | EH11: Fecha fin | EI11: Fecha ini | EJ11: Avance | EK11: Fecha fin | EL11: Fecha ini | EM11: Avance | EN11: Fecha fin | EO11: Fecha ini | EP11: Avance | EQ11: Fecha fin | ER11: Fecha ini | ES11: Avance | ET11: Fecha fin | EU11: Fecha ini | EV11: Avance | EW11: Fecha fin | EX11: Fecha ini | EY11: Avance | EZ11: Fecha fin | FA11: Fecha ini | FB11: Avance | FC11: Fecha fin | FD11: Fecha ini | FE11: Avance | FF11: Fecha fin | FG11: Fecha ini | FH11: Avance | FI11: Fecha fin | FJ11: Fecha ini | FK11: Avance | FL11: Fecha fin | FM11: Fecha ini | FN11: Avance | FO11: Fecha fin | FP11: Fecha ini | FQ11: Avance | FR11: Fecha fin | FS11: Fecha ini | FT11: Avance | FU11: Fecha fin | FV11: Fecha ini | FW11: Avance | FX11: Fecha fin | FY11: Fecha ini | FZ11: Avance | GA11: Fecha fin | GB11: Fecha ini | GC11: Avance | GD11: Fecha fin | GE11: Fecha ini | GF11: Avance | GG11: Fecha fin | GH11: Fecha ini | GI11: Avance | GJ11: Fecha fin | GK11: Fecha ini | GL11: Avance | GM11: Fecha fin | GN11: Fecha ini | GO11: Avance | GP11: Fecha fin | GQ11: Avance | GR11: Inicio | GS11: Terminación | GT11: Facturación | GU11: Acta | GV11: Fecha ini | GW11: Avance | GX11: Fecha fin | GY11: Fecha ini | GZ11: Avance | HA11: Fecha fin | HB11: Fecha ini | HC11: Avance | HD11: Fecha fin | HE11: Fecha ini | HF11: Avance | HG11: Fecha fin | HH11: Fecha ini | HI11: Avance | HJ11: Fecha fin | HK11: Avance | HL11: Inicio | HM11: Terminación | HN11: Facturación | HO11: Acta | HP11: CUMPLE ENSAYO | HR11: Fecha ini | HS11: Avance | HT11: Fecha fin | HU11: Fecha ini | HV11: Avance | HW11: Fecha fin | HX11: Fecha ini | HY11: Avance | HZ11: Fecha fin | IA11: Fecha ini | IB11: Avance | IC11: Fecha fin | ID11: Fecha ini | IE11: Avance | IF11: Fecha fin | IG11: Fecha | IH11: Fecha ini | II11: Avance | IJ11: Fecha fin | IK11: Fecha ini | IL11: Avance | IM11: Fecha fin | IN11: Avance | IO11: Inicio | IP11: Terminación | IQ11: Facturación | IR11: Acta | IS11: VANO [m] | IT11: TENDIDO | IU11: Fecha ini | IV11: Avance | IW11: Fecha fin | IX11: Fecha ini | IY11: Avance | IZ11: Fecha fin | JA11: Fecha ini | JB11: Avance | JC11: Fecha fin | JD11: km | JE11: Fecha ini | JF11: Avance | JG11: Fecha fin | JH11: km | JI11: Fecha ini | JJ11: Avance | JK11: Fecha fin | JL11: km | JM11: Fecha ini | JN11: Avance | JO11: Fecha fin | JP11: km | JQ11: Fecha ini | JR11: Avance | JS11: Fecha fin | JT11: km | JU11: Fecha ini | JV11: Avance | JW11: Fecha fin | JX11: km | JY11: Fecha ini | JZ11: Avance | KA11: Fecha fin | KB11: km | KC11: Fecha ini | KD11: Avance | KE11: Fecha fin | KF11: km | KG11: Fecha ini | KH11: Avance | KI11: Fecha fin | KK11: Fecha ini | KL11: Avance | KM11: Fecha fin | KN11: Fecha ini | KO11: Avance | KP11: Fecha fin | KQ11: Fecha ini | KR11: Avance - Placas | KS11: Fecha fin | KT11: Avance | KU11: Realizados | KV11: Inicio | KW11: Terminación | KX11: Fecha ini | KY11: Avance | KZ11: Fecha fin | LA11: km | LB11: Fecha ini | LC11: Avance | LD11: Fecha fin | LE11: km | LF11: Fecha ini | LG11: Avance | LH11: Fecha fin | LI11: km | LJ11: Fecha ini | LK11: Avance | LL11: Fecha fin | LM11: Fecha ini | LN11: Avance | LO11: Fecha fin | LP11: Fecha ini | LQ11: Avance | LR11: Fecha fin | LS11: Fecha ini | LT11: Avance | LU11: Fecha fin | LV11: Avance | LW11: Realizados | LX11: Inicio | LY11: Terminación | LZ11: Fecha ini | MA11: Avance | MB11: Fecha fin | MC11: km | MD11: Fecha ini | ME11: Avance | MF11: Fecha fin | MG11: km | MH11: Fecha ini | MI11: Avance | MJ11: Fecha fin | MK11: km | ML11: Fecha ini | MM11: Avance | MN11: Fecha fin | MO11: Fecha ini | MP11: Avance | MQ11: Fecha fin | MR11: Fecha ini | MS11: Avance | MT11: Fecha fin | MU11: Fecha ini | MV11: Avance | MW11: Fecha fin | MX11: Avance | MY11: Realizados | MZ11: Inicio | NA11: Terminación | NB11: Avance | NC11: Realizados | ND11: Inicio | NE11: Terminación | NF11: Facturación | NG11: Acta | NH11: Inicio | NI11: Avance | NJ11: Final | NK11: Facturación | NL11: Acta | NM11: Avance | NN11: Realizados | NO11: Inicio | NP11: Terminación | NQ11: Avance | NR11: Realizados | NS11: Inicio | NT11: Terminación | NU11: Avance | NV11: Realizados | NW11: Inicio | NX11: Terminación | NY11: Inicio | NZ11: Avance | OA11: Final | OB11: Inicio | OC11: Avance | OD11: Final | OE11: Inicio | OF11: Avance | OG11: Final | OH11: Fecha ini | OI11: Avance | OJ11: Fecha fin | OK11: Fecha ini | OL11: Avance | OM11: Fecha fin | ON11: Fecha ini | OO11: Avance | OP11: Fecha fin | OQ11: Fecha ini | OR11: Avance | OS11: Fecha fin | OT11: Fecha ini | OU11: Avance | OV11: Fecha fin | OW11: Fecha ini | OX11: Avance | OY11: Fecha fin | OZ11: Fecha ini | PA11: Avance | PB11: Fecha fin | PC11: Fecha ini | PD11: Avance | PE11: Fecha fin | PF11: Fecha ini | PG11: Avance | PH11: Fecha fin | PI11: Fecha ini | PJ11: Avance | PK11: Fecha fin | PL11: Fecha ini | PM11: Avance | PN11: Fecha fin | PO11: Avance | PP11: Inicio | PQ11: Terminación | PR11: Facturación | PS11: Acta | PT11: Fecha ini | PU11: Avance | PV11: Fecha fin | PW11: Fecha ini | PX11: Avance | PY11: Fecha fin | PZ11: Fecha ini | QA11: Avance | QB11: Fecha fin | QC11: Fecha ini | QD11: Avance | QE11: Fecha fin | QF11: Avance | QG11: Inicio | QH11: Terminación | QI11: Facturación | QJ11: Acta | QL11: Avance | QM11: OBSERVACIONES | QN11: promedio condcutor tendido | QO11: FECHA INICIO | QP11: AVANCE | QQ11: FECHA FINAL | QR11: FECHA INICIO | QS11: AVANCE | QT11: FECHA FINAL
A12: 1 | B12: Portico | E12: Pórtico | IS12: 54.89 | IT12: TEND 4 | JA12: 45928 | JB12: 1 | JC12: 45928 | JD12: =JF12*$IS12/1000 -> 0.05489 | JE12: 45928 | JF12: 1 | JG12: 45928 | JH12: =JJ12*$IS12/1000 -> 0.05489 | JI12: 45928 | JJ12: 1 | JK12: 45928 | JL12: =JN12*$IS12/1000 -> 0.05489 | JM12: 45928 | JN12: 1 | JO12: 45928 | JP12: =JR12*$IS12/1000 -> 0.05489 | JQ12: 45928 | JR12: 1 | JS12: 45928 | JT12: =JV12*$IS12/1000 -> 0.05489 | JU12: 45928 | JV12: 1 | JW12: 45928 | KL12: 0 | KN12: 45928 | KO12: 1 | KP12: 45928 | KR12: 0 | KX12: 45940 | KY12: 1 | KZ12: 45940 | LA12: =LC12*$IS12/1000 -> 0.05489 | LB12: 45940 | LC12: 1 | LD12: 45940 | LE12: =LG12*$IS12/1000 -> 0.05489 | LF12: 45940 | LG12: 1 | LH12: 45940 | LI12: =LK12*$IS12/1000 -> 0.05489 | LJ12: 45940 | LK12: 1 | LL12: =IF(LJ12="","",LJ12) -> 45940 | LM12: 45940 | LN12: 1 | LO12: 45940 | LQ12: 0 | LS12: 45941 | LT12: 1 | LU12: 45941 | LZ12: 45940 | MA12: 1 | MB12: 45940 | MC12: =ME12*$IS12/1000 -> 0.05489 | MD12: 45940 | ME12: 1 | MF12: 45940 | MG12: =MI12*$IS12/1000 -> 0.05489 | MH12: 45940 | MI12: 1 | MJ12: 45940 | MK12: =MM12*$IS12/1000 -> 0.05489 | ML12: 45940 | MM12: 1 | MN12: 45940 | MO12: 45940 | MP12: 1 | MQ12: 45940 | MS12: 0 | MU12: 45941 | MV12: 1 | MW12: 45940 | PC12: N/A | PG12: 0
A13: 2 | B13: T001 | D13: HE | E13: D6 | F13: 11717.92 | G13: INST | H13: CRUZ | I13: INST | O13: Z | P13: Z | Q13: Z | R13: Z | S13: HELICOIDALES | AG13: =AD13/$AG$8 -> 0 | AH13: =AE13/$AH$8 -> 0 | AI13: =AF13/$AI$8 -> 0 | AM13: =AJ13/$AM$8 -> 0 | AN13: =AK13/$AN$8 -> 0 | AO13: =AL13/$AO$8 -> 0 | AS13: =IFERROR(AP13/$AS$8,0) -> 0 | AT13: =IFERROR(AQ13/$AT$8,0) -> 0 | AU13: =IFERROR(AR13/$AU$8,0) -> 0 | AW13: SI | AX13: =BY13 -> 1 | AY13: NO | BA13: 45495 | BB13: =PU13 -> 1 | BC13: =QI13 -> 0 | BD13: =QJ13 -> 0 | BE13: 45685 | BF13: =IF(BE13<>"",1,) -> 1 | BG13: 45689 | BH13: =IF(BG13<>"",1,) -> 1 | BI13: =BL13 -> 45693 | BJ13: 0.05 | BK13: =EW13 -> 45747 | BL13: 45693 | BM13: 1 | BN13: 45693 | BO13: 45693 | BP13: 1 | BQ13: 45694 | BR13: 45693 | BS13: 1 | BT13: 45694 | BU13: 45693 | BV13: 1 | BW13: 45693 | BX13: =IF(MIN(BL13,BO13,BR13,BU13)=0,"",MIN(BL13,BO13,BR13,BU13)) -> 45693 | BY13: =+(BV13+BS13+BP13+BM13)/4 -> 1 | BZ13: =IF(BY13=1,MAX(BN13,BQ13,BT13,BW13),"") -> 45694 | CA13: 45708 | CB13: 1 | CC13: =IF(CA13="","",CA13) -> 45708 | CD13: 45708 | CE13: 1 | CF13: =IF(CD13="","",CD13) -> 45708 | CG13: 45708 | CH13: 1 | CI13: =IF(CG13="","",CG13) -> 45708 | CJ13: 45708 | CK13: 1 | CL13: =IF(CJ13="","",CJ13) -> 45708 | CM13: =IF(MIN(CA13,CD13,CG13,CJ13)=0,"",MIN(CA13,CD13,CG13,CJ13)) -> 45708 | CN13: =+(CK13+CH13+CE13+CB13)/4 -> 1 | CO13: =IF(CN13=1,MAX(CC13,CF13,CI13,CL13),"") -> 45708 | CP13: 45694 | CQ13: 1 | CR13: 45694 | CS13: 45695 | CT13: 1 | CU13: 45695 | CV13: 45695 | CW13: 1 | CX13: 45695 | CY13: 45694 | CZ13: 1 | DA13: 45695 | DB13: =IF(MIN(CP13,CS13,CV13,CY13)=0,"",MIN(CP13,CS13,CV13,CY13)) -> 45694 | DC13: =+(CZ13+CW13+CT13+CQ13)/4 -> 1 | DD13: =IF(DC13=1,MAX(CR13,CU13,CX13,DA13),"") -> 45695 | DE13: 45744 | DF13: 1 | DG13: 45746 | DH13: 45744 | DI13: 1 | DJ13: 45746 | DK13: 45744 | DL13: 1 | DM13: 45746 | DN13: 45744 | DO13: 1 | DP13: 45746 | DQ13: =IF(MIN(DE13,DH13,DK13,DN13)=0,"",MIN(DE13,DH13,DK13,DN13)) -> 45744 | DR13: =+(DO13+DL13+DI13+DF13)/4 -> 1 | DS13: =IF(DR13=1,MAX(DG13,DJ13,DM13,DP13),"") -> 45746 | DT13: 45746 | DU13: 1 | DV13: 45746 | DW13: 45746 | DX13: 1 | DY13: 45746 | DZ13: 45746 | EA13: 1 | EB13: 45746 | EC13: 45746 | ED13: 1 | EE13: 45746 | EF13: =IF(MIN(DT13,DW13,DZ13,EC13)=0,"",MIN(DT13,DW13,DZ13,EC13)) -> 45746 | EG13: =+(ED13+EA13+DX13+DU13)/4 -> 1 | EH13: =IF(EG13=1,MAX(DV13,DY13,EB13,EE13),"") -> 45746 | EI13: 45747 | EJ13: 1 | EK13: =IF(EI13="","",EI13) -> 45747 | EL13: 45746 | EM13: 1 | EN13: =IF(EL13="","",EL13) -> 45746 | EO13: 45746 | EP13: 1 | EQ13: =IF(EO13="","",EO13) -> 45746 | ER13: 45747 | ES13: 1 | ET13: =IF(ER13="","",ER13) -> 45747 | EU13: =IF(MIN(EI13,EL13,EO13,ER13)=0,"",MIN(EI13,EL13,EO13,ER13)) -> 45746 | EV13: =+(ES13+EP13+EM13+EJ13)/4 -> 1 | EW13: =IF(EV13=1,MAX(EK13,EN13,EQ13,ET13),"") -> 45747 | EY13: 0 | FB13: 0 | FE13: 0 | FH13: 0 | FJ13: =IF(MIN(EX13,FA13,FD13,FG13)=0,"",MIN(EX13,FA13,FD13,FG13)) | FK13: 0 | FL13: 0 | FM13: 45751 | FN13: 1 | FO13: 45752 | FP13: 45751 | FQ13: 1 | FR13: 45752 | FS13: 45751 | FT13: 1 | FU13: 45752 | FV13: 45751 | FW13: 1 | FX13: 45752 | FY13: =IF(MIN(FM13,FP13,FS13,FV13)=0,"",MIN(FM13,FP13,FS13,FV13)) -> 45751 | FZ13: =((FW13+FT13+FQ13+FN13)/4) -> 1 | GA13: =IF(FZ13=1,MAX(FO13,FR13,FU13,FX13),"") -> 45752 | GB13: 45747 | GC13: 1 | GD13: =IF(GB13="","",GB13) -> 45747 | GE13: 45746 | GF13: 1 | GG13: =IF(GE13="","",GE13) -> 45746 | GH13: 45746 | GI13: 1 | GJ13: =IF(GH13="","",GH13) -> 45746 | GK13: 45747 | GL13: 1 | GM13: =IF(GK13="","",GK13) -> 45747 | GN13: =IF(MIN(GB13,GE13,GH13,GK13)=0,"",MIN(GB13,GE13,GH13,GK13)) -> 45746 | GO13: =+(GL13+GI13+GF13+GC13)/4 -> 1 | GP13: =IF(GO13=1,MAX(GD13,GG13,GJ13,GM13),"") -> 45747 | GQ13: =(BY13*$BY$7)+(CN13*$CN$7)+(DR13*$DR$7)+(EV13*$EV$7)+(FZ13*$FZ$7) -> 1 | GR13: =+IF(MIN(BX13,CM13,DB13,DQ13,EF13,EU13,FY13)=0,"",MIN(BX13,CM13,DB13,DQ13,EF13,EU13,FY13)) -> 45693 | GS13: =+IF(GQ13=1,MAX(BZ13,CO13,DD13,DS13,EH13,EW13,GA13,GP13),"") -> 45752 | GV13: 45877 | GW13: 1 | GX13: 45885 | GY13: 45877 | GZ13: 1 | HA13: 45885 | HB13: 45877 | HC13: 1 | HD13: 45885 | HE13: 45877 | HF13: 1 | HG13: 45885 | HH13: =IF(MIN(GV13,GY13,HB13,HE13)=0,"",MIN(GV13,GY13,HB13,HE13)) -> 45877 | HI13: =+(HF13+HC13+GZ13+GW13)/4 -> 1 | HJ13: =IF(HI13=1,MAX(GX13,HA13,HD13,HG13),"") -> 45885 | HK13: 0 | HL13: =+IF(MIN(BE13,BI13,GP13,HH13)=0,"",MIN(BE13,BI13,GP13,HH13)) -> 45685 | HM13: =+IF(HK13=1,MAX(BE13,BI13,GS13,HJ13),"") | HR13: 45777 | HS13: 1 | HT13: 45777 | HU13: 45777 | HV13: 1 | HW13: 45777 | HX13: 45780 | HY13: 1 | HZ13: 45793 | IA13: 45794 | IB13: 1 | IC13: 45796 | ID13: 45804 | IE13: 1 | IF13: 45824 | IG13: 45807 | IH13: 45824 | II13: 1 | IJ13: 45793 | IK13: 45850 | IL13: 1 | IM13: 45850 | IN13: =(HV13*$HV$7)+(HY13*$HY$7)+(IB13*$IB$7)+(IE13*$IE$7) -> 1 | IO13: =+IF(MIN(HR13,HU13,HX13,IA13,ID13,IK13)=0,"",MIN(HR13,HU13,HX13,IA13,ID13,IK13)) -> 45777 | IP13: =+IF(IN13=1,MAX(HT13,HW13,HZ13,IC13,IF13,IM13),"") -> 45850 | IS13: 416.52 | IT13: TEND 4 | IV13: 0 | IX13: 45924 | IY13: 1 | IZ13: 45932 | JA13: 45930 | JB13: 1 | JC13: =IF(JA13="","",JA13) -> 45930 | JD13: =JF13*$IS13/1000 -> 0.41652 | JE13: 45936 | JF13: 1 | JG13: 45937 | JH13: =JJ13*$IS13/1000 -> 0.41652 | JI13: 45937 | JJ13: 1 | JK13: 45937 | JL13: =JN13*$IS13/1000 -> 0.41652 | JM13: 45937 | JN13: 1 | JO13: 45937 | JP13: =JR13*$IS13/1000 -> 0.41652 | JQ13: 45938 | JR13: 1 | JS13: 45938 | JT13: =JV13*$IS13/1000 -> 0.41652 | JU13: 45939 | JV13: 1 | JW13: 45939 | JX13: =JZ13*$IS13/1000 -> 0 | JZ13: 0 | KB13: =KD13*$IS13/1000 -> 0 | KD13: 0 | KF13: =KH13*$IS13/1000 -> 0 | KH13: 0 | KK13: 45941 | KL13: 1 | KM13: 45941 | KN13: 10/110/25 | KO13: 1 | KP13: 45940 | KQ13: 45941 | KR13: 1 | KS13: 45941 | KT13: 0 | KU13: =KT13*$IS13/1000 -> 0 | KV13: =+IF(MIN(JA13,JE13,JI13,JM13,JQ13,JU13,KK13,KN13,KQ13)=0,"",MIN(JA13,JE13,JI13,JM13,JQ13,JU13,KK13,KN13,KQ13)) -> 45930 | KW13: =+IF(KT13=1,MAX(KP13,KM13,JW13,JS13,JO13,JK13,JG13,JC13,KS13),"") | KX13: 45930 | KY13: 1 | KZ13: =IF(KX13="","",KX13) -> 45930 | LA13: =LC13*$IS13/1000 -> 0.41652 | LB13: 45934 | LC13: 1 | LD13: =IF(LB13="","",LB13) -> 45934 | LE13: =LG13*$IS13/1000 -> 0.41652 | LF13: 45934 | LG13: 1 | LH13: =IF(LF13="","",LF13) -> 45934 | LI13: =LK13*$IS13/1000 -> 0.41652 | LJ13: 45934 | LK13: 1 | LL13: =IF(LJ13="","",LJ13) -> 45934 | LM13: 45944 | LN13: 1 | LO13: 45944 | LP13: 20/20/25 | LQ13: 1 | LR13: 200/20/25 | LT13: 0 | LV13: 0 | LW13: =LV13*$IS13/1000 -> 0 | LX13: =+IF(MIN(KX13,LB13,LF13,LJ13,LM13,LP13,LS13)=0,"",MIN(KX13,LB13,LF13,LJ13,LM13,LP13,LS13)) -> 45930 | LY13: =IF(LV13=1,MAX(LU13),"") | MA13: 1 | MB13: =IF(LZ13="","",LZ13) | MC13: =ME13*$IS13/1000 -> 0.41652 | MD13: 45936 | ME13: 1 | MF13: =IF(MD13="","",MD13) -> 45936 | MG13: =MI13*$IS13/1000 -> 0.41652 | MH13: 45936 | MI13: 1 | MJ13: =IF(MH13="","",MH13) -> 45936 | MK13: =MM13*$IS13/1000 -> 0.41652 | ML13: 45936 | MM13: 1 | MN13: =IF(ML13="","",ML13) -> 45936 | MO13: 45944 | MP13: 1 | MQ13: 45944 | MR13: 20/20/25 | MS13: 1 | MT13: 200/20/25 | MV13: 0 | MX13: 0 | MY13: =MX13*$IS13/1000 -> 0 | MZ13: =+IF(MIN(LZ13,MD13,MH13,ML13,MO13,MR13,MU13)=0,"",MIN(LZ13,MD13,MH13,ML13,MO13,MR13,MU13)) -> 45936 | NA13: =IF(MX13=1,MAX(MW13),"") | NB13: 0 | NC13: =NB13*$IS13/1000 -> 0 | ND13: =+IF(MIN(MZ13,LX13,KV13,IU13)=0,"",MIN(MZ13,LX13,KV13,IU13)) -> 45930 | NE13: =+IF(IN13=1,MAX(IW13,KW13,LY13,NA13),"") -> 0 | NI13: 0 | NM13: 0 | NN13: =NM13*$IS13/1000 -> 0 | NQ13: 0 | NR13: =NQ13*$IS13/1000 -> 0 | NU13: 0 | NV13: =NU13*$IS13/1000 -> 0 | NZ13: 0 | OC13: 0 | OF13: 0 | OI13: 1 | OL13: 0.5 | OO13: 1 | OR13: =PD13 -> 0 | OU13: 0 | OX13: 0 | OZ13: 03/12/2024 3/02/2025 | PA13: 1 | PB13: =OZ13 -> 03/12/2024 3/02/2025 | PC13: N/A | PD13: 0 | PG13: 0 | PI13: 45693 | PJ13: 1 | PK13: ='Seg Diario'!HJ13 -> 45885 | PL13: =PI13 -> 45693 | PM13: =PJ13 -> 1 | PN13: =PK13 -> 45885 | PO13: 0.045 | PP13: =+IF(MIN(OH13,OK13,ON13,OQ13,OT13,OW13,OZ13,PC13,PI13,PL13)=0,"",MIN(OH13,OK13,ON13,OQ13,OT13,OW13,OZ13,PC13,PI13,PL13)) -> 45693 | PQ13: =+IF(PO13=1,MAX(OJ13,OM13,OP13,OS13,OV13,OY13,PB13,PE13,PK13,PN13),"") | PT13: 45495 | PU13: 1 | PV13: 45495 | PW13: 45527 | PX13: 1 | PY13: 45527 | QA13: 0 | QD13: 0.5 | QF13: 0.93745 | QG13: =+IF(MIN(PT13,PW13,PZ13,QC13)=0,"",MIN(PT13,PW13,PZ13,QC13)) -> 45495 | QH13: =+IF(QF13=1,MAX(PV13,PY13,QB13,QE13),"") | QL13: =(JN13+JR13+JV13+JZ13+KD13+KH13)/3 -> 1 | QM13: Cruce con vía primaria Mariquita - Ibagué, cruce con MEDIA TENSIÓN 34.5kV, cruce de línea MEDIA TENSIÓN 13.2kV | QN13: =(JN13+JR13+JV13)/3 -> 1 | QO13: 45913 | QP13: 1 | QQ13: 45916 | QR13: 45952 | QS13: 1 | QT13: 45952
A14: =1+A13 -> 3 | B14: T002 | D14: Z | E14: B4 | F14: 8310.73 | G14: MECT | H14: CRUZ | I14: INST | O14: Z | P14: Z | Q14: Z | R14: Z | S14: ZAPATA | AG14: =AD14/$AG$8 -> 0 | AH14: =AE14/$AH$8 -> 0 | AI14: =AF14/$AI$8 -> 0 | AM14: =AJ14/$AM$8 -> 0 | AN14: =AK14/$AN$8 -> 0 | AO14: =AL14/$AO$8 -> 0 | AS14: =IFERROR(AP14/$AS$8,0) -> 0 | AT14: =IFERROR(AQ14/$AT$8,0) -> 0 | AU14: =IFERROR(AR14/$AU$8,0) -> 0 | AW14: SI | AX14: =BY14 -> 1 | AY14: NO | BA14: 45491 | BB14: =PU14 -> 1 | BC14: =QI14 -> 0 | BD14: =QJ14 -> 0 | BE14: 45662 | BF14: =IF(BE14<>"",1,) -> 1 | BG14: 45749 | BH14: =IF(BG14<>"",1,) -> 1 | BI14: =BL14 -> 45702 | BJ14: 0 | BK14: =EW14 -> 45760 | BL14: 45702 | BM14: 1 | BN14: 45702 | BO14: 45702 | BP14: 1 | BQ14: 45702 | BR14: 45702 | BS14: 1 | BT14: 45702 | BU14: 45702 | BV14: 1 | BW14: 45702 | BX14: =IF(MIN(BL14,BO14,BR14,BU14)=0,"",MIN(BL14,BO14,BR14,BU14)) -> 45702 | BY14: =+(BV14+BS14+BP14+BM14)/4 -> 1 | BZ14: =IF(BY14=1,MAX(BN14,BQ14,BT14,BW14),"") -> 45702 | CA14: 45755 | CB14: 1 | CC14: =IF(CA14="","",CA14) -> 45755 | CD14: 45756 | CE14: 1 | CF14: =IF(CD14="","",CD14) -> 45756 | CG14: 45757 | CH14: 1 | CI14: =IF(CG14="","",CG14) -> 45757 | CJ14: 45755 | CK14: 1 | CL14: =IF(CJ14="","",CJ14) -> 45755 | CM14: =IF(MIN(CA14,CD14,CG14,CJ14)=0,"",MIN(CA14,CD14,CG14,CJ14)) -> 45755 | CN14: =+(CK14+CH14+CE14+CB14)/4 -> 1 | CO14: =IF(CN14=1,MAX(CC14,CF14,CI14,CL14),"") -> 45757 | CQ14: 0 | CT14: 0 | CW14: 0 | CZ14: 0 | DB14: =IF(MIN(CP14,CS14,CV14,CY14)=0,"",MIN(CP14,CS14,CV14,CY14)) | DC14: =+(CZ14+CW14+CT14+CQ14)/4 -> 0 | DD14: =IF(DC14=1,MAX(CR14,CU14,CX14,DA14),"") | DE14: 45756 | DF14: 1 | DG14: 45756 | DH14: 45757 | DI14: 1 | DJ14: 45757 | DK14: 45758 | DL14: 1 | DM14: 45758 | DN14: 45756 | DO14: 1 | DP14: 45756 | DQ14: =IF(MIN(DE14,DH14,DK14,DN14)=0,"",MIN(DE14,DH14,DK14,DN14)) -> 45756 | DR14: =+(DO14+DL14+DI14+DF14)/4 -> 1 | DS14: =IF(DR14=1,MAX(DG14,DJ14,DM14,DP14),"") -> 45758 | DT14: 45756 | DU14: 1 | DV14: 45757 | DW14: 45756 | DX14: 1 | DY14: 45757 | DZ14: 45757 | EA14: 1 | EB14: 45757 | EC14: 45756 | ED14: 1 | EE14: 45757 | EF14: =IF(MIN(DT14,DW14,DZ14,EC14)=0,"",MIN(DT14,DW14,DZ14,EC14)) -> 45756 | EG14: =+(ED14+EA14+DX14+DU14)/4 -> 1 | EH14: =IF(EG14=1,MAX(DV14,DY14,EB14,EE14),"") -> 45757 | EI14: 45758 | EJ14: 1 | EK14: =IF(EI14="","",EI14) -> 45758 | EL14: 45760 | EM14: 1 | EN14: =IF(EL14="","",EL14) -> 45760 | EO14: 45760 | EP14: 1 | EQ14: =IF(EO14="","",EO14) -> 45760 | ER14: 45758 | ES14: 1 | ET14: =IF(ER14="","",ER14) -> 45758 | EU14: =IF(MIN(EI14,EL14,EO14,ER14)=0,"",MIN(EI14,EL14,EO14,ER14)) -> 45758 | EV14: =+(ES14+EP14+EM14+EJ14)/4 -> 1 | EW14: =IF(EV14=1,MAX(EK14,EN14,EQ14,ET14),"") -> 45760 | EY14: 0 | FB14: 0 | FE14: 0 | FH14: 0 | FJ14: =IF(MIN(EX14,FA14,FD14,FG14)=0,"",MIN(EX14,FA14,FD14,FG14)) | FK14: 0 | FL14: =IF(FK14=1,MAX(EZ14,FC14,FF14,FI14),"") | FM14: 45761 | FN14: 1 | FO14: 45761 | FP14: 45768 | FQ14: 1 | FR14: 45768 | FS14: 45768 | FT14: 1 | FU14: 45768 | FV14: 45761 | FW14: 1 | FX14: 45761 | FY14: =IF(MIN(FM14,FP14,FS14,FV14)=0,"",MIN(FM14,FP14,FS14,FV14)) -> 45761 | FZ14: =((FW14+FT14+FQ14+FN14)/4) -> 1 | GA14: =IF(FZ14=1,MAX(FO14,FR14,FU14,FX14),"") -> 45768 | GB14: 45758 | GC14: 1 | GD14: =IF(GB14="","",GB14) -> 45758 | GE14: 45760 | GF14: 1 | GG14: =IF(GE14="","",GE14) -> 45760 | GH14: 45760 | GI14: 1 | GJ14: =IF(GH14="","",GH14) -> 45760 | GK14: 45758 | GL14: 1 | GM14: =IF(GK14="","",GK14) -> 45758 | GN14: =IF(MIN(GB14,GE14,GH14,GK14)=0,"",MIN(GB14,GE14,GH14,GK14)) -> 45758 | GO14: =+(GL14+GI14+GF14+GC14)/4 -> 1 | GP14: =IF(GO14=1,MAX(GD14,GG14,GJ14,GM14),"") -> 45760 | GQ14: =(BY14*$BY$7)+(CN14*$CN$7)+(DR14*$DR$7)+(EV14*$EV$7)+(FZ14*$FZ$7) -> 1 | GR14: =+IF(MIN(BX14,CM14,DB14,DQ14,EF14,EU14,FY14)=0,"",MIN(BX14,CM14,DB14,DQ14,EF14,EU14,FY14)) -> 45702 | GS14: =+IF(GQ14=1,MAX(BZ14,CO14,DD14,DS14,EH14,EW14,GA14,GP14),"") -> 45768 | GV14: 45855 | GW14: 1 | GX14: 45864 | GY14: 45855 | GZ14: 1 | HA14: 45864 | HB14: 45855 | HC14: 1 | HD14: 45864 | HE14: 45855 | HF14: 1 | HG14: 45864 | HH14: =IF(MIN(GV14,GY14,HB14,HE14)=0,"",MIN(GV14,GY14,HB14,HE14)) -> 45855 | HI14: =+(HF14+HC14+GZ14+GW14)/4 -> 1 | HJ14: =IF(HI14=1,MAX(GX14,HA14,HD14,HG14),"") -> 45864 | HK14: 0 | HL14: =+IF(MIN(BE14,BI14,GP14,HH14)=0,"",MIN(BE14,BI14,GP14,HH14)) -> 45662 | HM14: =+IF(HK14=1,MAX(BE14,BI14,GS14,HJ14),"") | HR14: 45792 | HS14: 1 | HT14: 45796 | HU14: 45796 | HV14: 1 | HW14: 45796 | HX14: 45798 | HY14: 1 | HZ14: 45800 | IA14: 45801 | IB14: 1 | IC14: 45801 | ID14: 45802 | IE14: 1 | IF14: 45824 | IG14: 45817 | IH14: 45814 | II14: 1 | IJ14: 45814 | IK14: 45827 | IL14: 1 | IM14: 45827 | IN14: =(HV14*$HV$7)+(HY14*$HY$7)+(IB14*$IB$7)+(IE14*$IE$7) -> 1 | IO14: =+IF(MIN(HR14,HU14,HX14,IA14,ID14,IK14)=0,"",MIN(HR14,HU14,HX14,IA14,ID14,IK14)) -> 45792 | IP14: =+IF(IN14=1,MAX(HT14,HW14,HZ14,IC14,IF14,IM14),"") -> 45827 | IS14: 230.06 | IT14: TEND 4 | IV14: 0 | IX14: 45924 | IY14: 1 | IZ14: 45933 | JA14: 45831 | JB14: 1 | JC14: =IF(JA14="","",JA14) -> 45831 | JD14: =JF14*$IS14/1000 -> 0.23006 | JE14: 45936 | JF14: 1 | JG14: 45936 | JH14: =JJ14*$IS14/1000 -> 0.23006 | JI14: 45937 | JJ14: 1 | JK14: 45937 | JL14: =JN14*$IS14/1000 -> 0.23006 | JM14: 45937 | JN14: 1 | JO14: 45937 | JP14: =JR14*$IS14/1000 -> 0.23006 | JQ14: 45938 | JR14: 1 | JS14: 45938 | JT14: =JV14*$IS14/1000 -> 0.23006 | JU14: 45939 | JV14: 1 | JW14: 45939 | JX14: =JZ14*$IS14/1000 -> 0 | JZ14: 0 | KB14: =KD14*$IS14/1000 -> 0 | KD14: 0 | KF14: =KH14*$IS14/1000 -> 0 | KH14: 0 | KK14: 45944 | KL14: 1 | KM14: 45944 | KN14: 45942 | KO14: 1 | KP14: 45942 | KQ14: 45941 | KR14: 1 | KS14: 45942 | KT14: 0 | KU14: =KT14*$IS14/1000 -> 0 | KV14: =+IF(MIN(JA14,JE14,JI14,JM14,JQ14,JU14,KK14,KN14,KQ14)=0,"",MIN(JA14,JE14,JI14,JM14,JQ14,JU14,KK14,KN14,KQ14)) -> 45831 | KW14: =+IF(KT14=1,MAX(KP14,KM14,JW14,JS14,JO14,JK14,JG14,JC14,KS14),"") | KX14: 45929 | KY14: 1 | KZ14: =IF(KX14="","",KX14) -> 45929 | LA14: =LC14*$IS14/1000 -> 0.23006 | LB14: 45934 | LC14: 1 | LD14: =IF(LB14="","",LB14) -> 45934 | LE14: =LG14*$IS14/1000 -> 0.23006 | LF14: 45934 | LG14: 1 | LH14: =IF(LF14="","",LF14) -> 45934 | LI14: =LK14*$IS14/1000 -> 0.23006 | LJ14: 45934 | LK14: 1 | LL14: =IF(LJ14="","",LJ14) -> 45934 | LM14: 45945 | LN14: 1 | LO14: 45945 | LQ14: 0 | LT14: 0 | LV14: 0 | LW14: =LV14*$IS14/1000 -> 0 | LX14: =+IF(MIN(KX14,LB14,LF14,LJ14,LM14,LP14,LS14)=0,"",MIN(KX14,LB14,LF14,LJ14,LM14,LP14,LS14)) -> 45929 | LY14: =IF(LV14=1,MAX(LU14),"") | LZ14: 45929 | MA14: 1 | MB14: =IF(LZ14="","",LZ14) -> 45929 | MC14: =ME14*$IS14/1000 -> 0.23006 | MD14: 45936 | ME14: 1 | MF14: =IF(MD14="","",MD14) -> 45936 | MG14: =MI14*$IS14/1000 -> 0.23006 | MH14: 45936 | MI14: 1 | MJ14: =IF(MH14="","",MH14) -> 45936 | MK14: =MM14*$IS14/1000 -> 0.23006 | ML14: 45936 | MM14: 1 | MN14: =IF(ML14="","",ML14) -> 45936 | MO14: 45946 | MP14: 1 | MQ14: 45946 | MS14: 0 | MV14: 0 | MX14: 0 | MY14: =MX14*$IS14/1000 -> 0 | MZ14: =+IF(MIN(LZ14,MD14,MH14,ML14,MO14,MR14,MU14)=0,"",MIN(LZ14,MD14,MH14,ML14,MO14,MR14,MU14)) -> 45929 | NA14: =IF(MX14=1,MAX(MW14),"") | NB14: 0 | NC14: =NB14*$IS14/1000 -> 0 | ND14: =+IF(MIN(MZ14,LX14,KV14,IU14)=0,"",MIN(MZ14,LX14,KV14,IU14)) -> 45831 | NE14: =+IF(IN14=1,MAX(IW14,KW14,LY14,NA14),"") -> 0 | NI14: 0 | NM14: 0 | NN14: =NM14*$IS14/1000 -> 0 | NQ14: 0 | NR14: =NQ14*$IS14/1000 -> 0 | NU14: 0 | NV14: =NU14*$IS14/1000 -> 0 | NX14: =IF(NU14=1,MAX(NT14),"") | NZ14: 0 | OC14: 0 | OF14: 0 | OI14: 1 | OL14: 0.5 | OO14: 1 | OR14: =PD14 -> 0 | OU14: 0 | OX14: 0 | OZ14: 45700 | PA14: 1 | PB14: =OZ14 -> 45700 | PC14: N/A | PD14: 0 | PG14: 0 | PI14: 45702 | PJ14: 1 | PK14: ='Seg Diario'!HJ14 -> 45864 | PL14: =PI14 -> 45702 | PM14: =PJ14 -> 1 | PN14: =PK14 -> 45864 | PO14: 0.045 | PP14: =+IF(MIN(OH14,OK14,ON14,OQ14,OT14,OW14,OZ14,PC14,PI14,PL14)=0,"",MIN(OH14,OK14,ON14,OQ14,OT14,OW14,OZ14,PC14,PI14,PL14)) -> 45700 | PQ14: =+IF(PO14=1,MAX(OJ14,OM14,OP14,OS14,OV14,OY14,PB14,PE14,PK14,PN14),"") | PT14: 45491 | PU14: 1 | PV14: 45491 | PW14: 45527 | PX14: 1 | PY14: 45527 | QA14: 0 | QD14: 0.5 | QF14: 0.93745 | QG14: =+IF(MIN(PT14,PW14,PZ14,QC14)=0,"",MIN(PT14,PW14,PZ14,QC14)) -> 45491 | QH14: =+IF(QF14=1,MAX(PV14,PY14,QB14,QE14),"") | QL14: =(JN14+JR14+JV14+JZ14+KD14+KH14)/3 -> 1 | QM14: Cruce con línea de 13,2 kV, poste 1.44m a eje de línea | QN14: =(JN14+JR14+JV14)/3 -> 1 | QO14: 45890 | QP14: 1 | QQ14: 45890 | QR14: 45911 | QS14: 1 | QT14: 45911
A15: =1+A14 -> 4 | B15: T003 | D15: HE | E15: B4 | F15: 8247.84 | H15: INST | I15: INST | O15: Z | P15: Z | Q15: Z | R15: Z | S15: HELICOIDALES | AG15: =AD15/$AG$8 -> 0 | AH15: =AE15/$AH$8 -> 0 | AI15: =AF15/$AI$8 -> 0 | AM15: =AJ15/$AM$8 -> 0 | AN15: =AK15/$AN$8 -> 0 | AO15: =AL15/$AO$8 -> 0 | AS15: =IFERROR(AP15/$AS$8,0) -> 0 | AT15: =IFERROR(AQ15/$AT$8,0) -> 0 | AU15: =IFERROR(AR15/$AU$8,0) -> 0 | AW15: SI | AX15: =BY15 -> 1 | AY15: NO | AZ15: CAMBIO ANLA | BA15: 45491 | BB15: =PU15 -> 1 | BC15: =QI15 -> 0 | BD15: =QJ15 -> 0 | BE15: 45662 | BF15: =IF(BE15<>"",1,) -> 1 | BG15: 45720 | BH15: =IF(BG15<>"",1,) -> 1 | BI15: =BL15 -> 45794 | BJ15: 0 | BK15: =EW15 -> 45801 | BL15: 45794 | BM15: 1 | BN15: 45794 | BO15: 45794 | BP15: 1 | BQ15: 45794 | BR15: 45794 | BS15: 1 | BT15: 45794 | BU15: 45794 | BV15: 1 | BW15: 45794 | BX15: =IF(MIN(BL15,BO15,BR15,BU15)=0,"",MIN(BL15,BO15,BR15,BU15)) -> 45794 | BY15: =+(BV15+BS15+BP15+BM15)/4 -> 1 | BZ15: =IF(BY15=1,MAX(BN15,BQ15,BT15,BW15),"") -> 45794 | CA15: 45798 | CB15: 1 | CC15: =IF(CA15="","",CA15) -> 45798 | CD15: 45798 | CE15: 1 | CF15: =IF(CD15="","",CD15) -> 45798 | CG15: 45798 | CH15: 1 | CI15: =IF(CG15="","",CG15) -> 45798 | CJ15: 45798 | CK15: 1 | CL15: =IF(CJ15="","",CJ15) -> 45798 | CM15: =IF(MIN(CA15,CD15,CG15,CJ15)=0,"",MIN(CA15,CD15,CG15,CJ15)) -> 45798 | CN15: =+(CK15+CH15+CE15+CB15)/4 -> 1 | CO15: =IF(CN15=1,MAX(CC15,CF15,CI15,CL15),"") -> 45798 | CP15: 45794 | CQ15: 1 | CR15: 45794 | CS15: 45796 | CT15: 1 | CU15: 45796 | CV15: 45796 | CW15: 1 | CX15: 45796 | CY15: 45796 | CZ15: 1 | DA15: 45796 | DB15: =IF(MIN(CP15,CS15,CV15,CY15)=0,"",MIN(CP15,CS15,CV15,CY15)) -> 45794 | DC15: =+(CZ15+CW15+CT15+CQ15)/4 -> 1 | DD15: =IF(DC15=1,MAX(CR15,CU15,CX15,DA15),"") -> 45796 | DE15: 45799 | DF15: 1 | DG15: 45801 | DH15: 45800 | DI15: 1 | DJ15: 45801 | DK15: 45799 | DL15: 1 | DM15: 45801 | DN15: 45799 | DO15: 1 | DP15: 45801 | DQ15: =IF(MIN(DE15,DH15,DK15,DN15)=0,"",MIN(DE15,DH15,DK15,DN15)) -> 45799 | DR15: 1 | DS15: 45801 | DT15: 45798 | DU15: 1 | DV15: 45801 | DW15: 45798 | DX15: 1 | DY15: 45801 | DZ15: 45798 | EA15: 1 | EB15: 45801 | EC15: 45798 | ED15: 1 | EE15: 45801 | EF15: =IF(MIN(DT15,DW15,DZ15,EC15)=0,"",MIN(DT15,DW15,DZ15,EC15)) -> 45798 | EG15: =+(ED15+EA15+DX15+DU15)/4 -> 1 | EH15: =IF(EG15=1,MAX(DV15,DY15,EB15,EE15),"") -> 45801 | EI15: 45801 | EJ15: 1 | EK15: =IF(EI15="","",EI15) -> 45801 | EL15: 45801 | EM15: 1 | EN15: =IF(EL15="","",EL15) -> 45801 | EO15: 45801 | EP15: 1 | EQ15: =IF(EO15="","",EO15) -> 45801 | ER15: 45801 | ES15: 1 | ET15: =IF(ER15="","",ER15) -> 45801 | EU15: =IF(MIN(EI15,EL15,EO15,ER15)=0,"",MIN(EI15,EL15,EO15,ER15)) -> 45801 | EV15: =+(ES15+EP15+EM15+EJ15)/4 -> 1 | EW15: =IF(EV15=1,MAX(EK15,EN15,EQ15,ET15),"") -> 45801 | EY15: 0 | FB15: 0 | FE15: 0 | FH15: 0 | FJ15: =IF(MIN(EX15,FA15,FD15,FG15)=0,"",MIN(EX15,FA15,FD15,FG15)) | FK15: 0 | FL15: =IF(FK15=1,MAX(EZ15,FC15,FF15,FI15),"") | FM15: 45821 | FN15: 1 | FO15: 45821 | FP15: 45821 | FQ15: 1 | FR15: 45821 | FS15: 45821 | FT15: 1 | FU15: 45821 | FV15: 45821 | FW15: 1 | FX15: 45821 | FY15: =IF(MIN(FM15,FP15,FS15,FV15)=0,"",MIN(FM15,FP15,FS15,FV15)) -> 45821 | FZ15: =((FW15+FT15+FQ15+FN15)/4) -> 1 | GA15: =IF(FZ15=1,MAX(FO15,FR15,FU15,FX15),"") -> 45821 | GB15: 45801 | GC15: 1 | GD15: =IF(GB15="","",GB15) -> 45801 | GE15: 45801 | GF15: 1 | GG15: =IF(GE15="","",GE15) -> 45801 | GH15: 45801 | GI15: 1 | GJ15: =IF(GH15="","",GH15) -> 45801 | GK15: 45801 | GL15: 1 | GM15: =IF(GK15="","",GK15) -> 45801 | GN15: =IF(MIN(GB15,GE15,GH15,GK15)=0,"",MIN(GB15,GE15,GH15,GK15)) -> 45801 | GO15: =+(GL15+GI15+GF15+GC15)/4 -> 1 | GP15: =IF(GO15=1,MAX(GD15,GG15,GJ15,GM15),"") -> 45801 | GQ15: =(BY15*$BY$7)+(CN15*$CN$7)+(DR15*$DR$7)+(EV15*$EV$7)+(FZ15*$FZ$7) -> 1 | GR15: =+IF(MIN(BX15,CM15,DB15,DQ15,EF15,EU15,FY15)=0,"",MIN(BX15,CM15,DB15,DQ15,EF15,EU15,FY15)) -> 45794 | GS15: =+IF(GQ15=1,MAX(BZ15,CO15,DD15,DS15,EH15,EW15,GA15,GP15),"") -> 45821 | GV15: 45855 | GW15: 1 | GX15: 45868 | GY15: 45855 | GZ15: 1 | HA15: 45868 | HB15: 45855 | HC15: 1 | HD15: 45868 | HE15: 45855 | HF15: 1 | HG15: 45868 | HH15: =IF(MIN(GV15,GY15,HB15,HE15)=0,"",MIN(GV15,GY15,HB15,HE15)) -> 45855 | HI15: =+(HF15+HC15+GZ15+GW15)/4 -> 1 | HJ15: =IF(HI15=1,MAX(GX15,HA15,HD15,HG15),"") -> 45868 | HK15: 0 | HL15: =+IF(MIN(BE15,BI15,GP15,HH15)=0,"",MIN(BE15,BI15,GP15,HH15)) -> 45662 | HM15: =+IF(HK15=1,MAX(BE15,BI15,GS15,HJ15),"") | HR15: 45808 | HS15: 1 | HT15: 45808 | HU15: 45825 | HV15: 1 | HW15: 45825 | HX15: 45826 | HY15: 1 | HZ15: 45827 | IA15: 45796 | IB15: 1 | IC15: 45829 | ID15: 45831 | IE15: 1 | IF15: 45832 | IG15: 45834 | IH15: 45834 | II15: 1 | IJ15: 45834 | IK15: 45834 | IL15: 1 | IM15: 45834 | IN15: =(HV15*$HV$7)+(HY15*$HY$7)+(IB15*$IB$7)+(IE15*$IE$7) -> 1 | IO15: =+IF(MIN(HR15,HU15,HX15,IA15,ID15,IK15)=0,"",MIN(HR15,HU15,HX15,IA15,ID15,IK15)) -> 45796 | IP15: =+IF(IN15=1,MAX(HT15,HW15,HZ15,IC15,IF15,IM15),"") -> 45834 | IS15: 287.98 | IT15: TEND 4 | IV15: 0 | IY15: 0 | JA15: 45929 | JB15: 1 | JC15: =IF(JA15="","",JA15) -> 45929 | JD15: =JF15*$IS15/1000 -> 0.28798 | JE15: 45936 | JF15: 1 | JG15: 45937 | JH15: =JJ15*$IS15/1000 -> 0.28798 | JI15: 45937 | JJ15: 1 | JK15: 45937 | JL15: =JN15*$IS15/1000 -> 0.28798 | JM15: 45937 | JN15: 1 | JO15: 45937 | JP15: =JR15*$IS15/1000 -> 0.28798 | JQ15: 45938 | JR15: 1 | JS15: 45938 | JT15: =JV15*$IS15/1000 -> 0.28798 | JU15: 45939 | JV15: 1 | JW15: 45939 | JX15: =JZ15*$IS15/1000 -> 0 | JZ15: 0 | KB15: =KD15*$IS15/1000 -> 0 | KD15: 0 | KF15: =KH15*$IS15/1000 -> 0 | KH15: 0 | KK15: 45943 | KL15: 1 | KM15: 45943 | KN15: 45943 | KO15: 1 | KP15: 45943 | KQ15: 45941 | KR15: 1 | KS15: 45942 | KT15: 0 | KU15: =KT15*$IS15/1000 -> 0 | KV15: =+IF(MIN(JA15,JE15,JI15,JM15,JQ15,JU15,KK15,KN15,KQ15)=0,"",MIN(JA15,JE15,JI15,JM15,JQ15,JU15,KK15,KN15,KQ15)) -> 45929 | KW15: =+IF(KT15=1,MAX(KP15,KM15,JW15,JS15,JO15,JK15,JG15,JC15,KS15),"") | KX15: 45929 | KY15: 1 | KZ15: =IF(KX15="","",KX15) -> 45929 | LA15: =LC15*$IS15/1000 -> 0.28798 | LB15: 45930 | LC15: 1 | LD15: =IF(LB15="","",LB15) -> 45930 | LE15: =LG15*$IS15/1000 -> 0.28798 | LF15: 45934 | LG15: 1 | LH15: =IF(LF15="","",LF15) -> 45934 | LI15: =LK15*$IS15/1000 -> 0.28798 | LJ15: 45934 | LK15: 1 | LL15: =IF(LJ15="","",LJ15) -> 45934 | LM15: 45946 | LN15: 1 | LO15: 45946 | LP15: 20/20/25 | LQ15: 1 | LR15: 200/20/25 | LT15: 0 | LV15: 0 | LW15: =LV15*$IS15/1000 -> 0 | LX15: =+IF(MIN(KX15,LB15,LF15,LJ15,LM15,LP15,LS15)=0,"",MIN(KX15,LB15,LF15,LJ15,LM15,LP15,LS15)) -> 45929 | LY15: =IF(LV15=1,MAX(LU15),"") | LZ15: 45929 | MA15: 1 | MB15: =IF(LZ15="","",LZ15) -> 45929 | MC15: =ME15*$IS15/1000 -> 0.28798 | MD15: 45930 | ME15: 1 | MF15: =IF(MD15="","",MD15) -> 45930 | MG15: =MI15*$IS15/1000 -> 0.28798 | MH15: 45936 | MI15: 1 | MJ15: =IF(MH15="","",MH15) -> 45936 | MK15: =MM15*$IS15/1000 -> 0.28798 | ML15: 45936 | MM15: 1 | MN15: =IF(ML15="","",ML15) -> 45936 | MO15: 45946 | MP15: 1 | MQ15: 45946 | MR15: 20/20/25 | MS15: 1 | MT15: 200/20/25 | MV15: 0 | MX15: 0 | MY15: =MX15*$IS15/1000 -> 0 | MZ15: =+IF(MIN(LZ15,MD15,MH15,ML15,MO15,MR15,MU15)=0,"",MIN(LZ15,MD15,MH15,ML15,MO15,MR15,MU15)) -> 45929 | NA15: =IF(MX15=1,MAX(MW15),"") | NB15: 0 | NC15: =NB15*$IS15/1000 -> 0 | ND15: =+IF(MIN(MZ15,LX15,KV15,IU15)=0,"",MIN(MZ15,LX15,KV15,IU15)) -> 45929 | NE15: =+IF(IN15=1,MAX(IW15,KW15,LY15,NA15),"") -> 0 | NI15: 0 | NM15: 0 | NN15: =NM15*$IS15/1000 -> 0 | NQ15: 0 | NR15: =NQ15*$IS15/1000 -> 0 | NU15: 0 | NV15: =NU15*$IS15/1000 -> 0 | NX15: =IF(NU15=1,MAX(NT15),"") | NZ15: 0 | OC15: 0 | OF15: 0 | OI15: 1 | OL15: 0.5 | OO15: 1 | OR15: =PD15 -> 0 | OU15: 0 | OX15: 0 | OZ15: 45704 | PA15: 1 | PB15: =OZ15 -> 45704 | PC15: N/A | PD15: 0 | PG15: 0 | PI15: 45794 | PJ15: 1 | PK15: ='Seg Diario'!HJ15 -> 45868 | PL15: =PI15 -> 45794 | PM15: =PJ15 -> 1 | PN15: =PK15 -> 45868 | PO15: 0.045 | PP15: =+IF(MIN(OH15,OK15,ON15,OQ15,OT15,OW15,OZ15,PC15,PI15,PL15)=0,"",MIN(OH15,OK15,ON15,OQ15,OT15,OW15,OZ15,PC15,PI15,PL15)) -> 45704 | PQ15: =+IF(PO15=1,MAX(OJ15,OM15,OP15,OS15,OV15,OY15,PB15,PE15,PK15,PN15),"") | PT15: 45491 | PU15: 1 | PV15: 45491 | PW15: 45527 | PX15: 1 | PY15: 45527 | QA15: 0 | QD15: 0.5 | QF15: 0.93745 | QG15: =+IF(MIN(PT15,PW15,PZ15,QC15)=0,"",MIN(PT15,PW15,PZ15,QC15)) -> 45491 | QH15: =+IF(QF15=1,MAX(PV15,PY15,QB15,QE15),"") | QL15: =(JN15+JR15+JV15+JZ15+KD15+KH15)/3 -> 1 | QN15: =(JN15+JR15+JV15)/3 -> 1 | QO15: 45890 | QP15: 1 | QQ15: 45890 | QR15: 45952 | QS15: 1 | QT15: 45952
