Workbook
Name _ftn3: #REF!
Name _ftnref3: #REF!
Name Equipos: '[1]Eq F18'!$A$10:$H$87
Name Material: '[1]Mat F19'!$A$10:$G$1003
Name MO: [1]Mo!$B$3:$D$32
Name Transporte: [1]Transp!$A$8:$E$39

Sheet CANT OOCC
B1: OBRA CIVIL
Y2: 0.4 | AR2: 0.05 | BE2: 0.1 | CK2: 0.4 | CR2: 0.05 | CT2: =SUM(Y2:CS2) -> 1
A3: h | B3: TORRE | C3: DISEÑO CONSTRUIDO | D3: Replanteo topografico | E3: Patas | F3: Cerramiento | K3: EXCAVACION | AA3: SOLADO | AU3: INSTALACION DE ACERO | BG3: VACIADO EN CONCRETO | CM3: Compactacion | CT3: TOTAL | CU3: Ejecutado por | CV3: COMENTARIO
F4: Cantidad de madera a utilizar (un) | G4: Cantidad de lona o alambre de púa a utilizara (m) | H4: señalizacion, punto ecolog, baño (0/1) | I4: Notas | J4: Cerramiento finalizado | K4: Cuadrilla o encargado en ejecutar la tarea (nombre) | L4: FT-022 MARCACIÓN DE EXCAVACIONES (0/1) | M4: FT-023 PLANILLA CONTROL DE EXCAVACIONES (0/1) | N4: FT-058 CONTROL DE EXCAVACIONES (0/1) | O4: Excavacion (manual / maquina) | P4: Metros de excavacion (m³) | Q4: Pruebas de capacidad portante del terreno con el penetrometro (0/1) | R4: FT-922 CONCEPTO DE ENTIBADO (0/1) | S4: FT-926 MARCACIÓN PILOTES (0/1) | T4: FT-927 REGISTRO DE CANTIDADES EN OBRA INSTLADAO PILOTES (0/1) | U4: FT-925 PRUEBA DE CARGA EN PILOTES (0/1) | V4: FT-928 REGISTRO DE TORQUE (0/1) | W4: FT-929 LOCALIZACIÓN FINAL PILOTES (0/1) | X4: Monitoreo arqueologico (en ejecucion /liberada) | Y4: Ejecucion de excavacion patas | Z4: Observaciones | AA4: Ingreso de materiales (Vehiculo, manual, mular o teleférico) | AB4: Cantidad de agua calculada a utilizar (m³) | AC4: Cantidad de agua utilizada en campo (m³) | AD4: Desviacion de la cantidad de agua utilizada (m³) | AE4: Observaciones | AF4: Cantidad de arena calculada a utilizar (m³) | AG4: Cantidad de arena utilizada en campo (m³) | AH4: Desviacion de la candidad arena utilizada (m³) | AI4: Observaciones | AJ4: cantidad de grava calculada a utilizar (m³) | AK4: cantidad de grava utilizada en campo (m³) | AL4: Desviacion de la cantidad de grava utilizada (m³) | AM4: Observaciones | AN4: Cantidad de cemento calculado a utilizar (kl) | AO4: Cantidad de cemento utilizado en campo (kl) | AP4: Desviacion de la cantidad de semento utilizado (kg) | AQ4: Observaciones | AR4: Ejecucion del solado patas A B C y D (0/1) | AS4: Observaciones | AT4: Soldadura de las prolongas a los stup para patas A B C y D (0/1) | AU4: Ingreso del acero a sitio de torre (Vehiculo, manual, mular o teleférico) | AV4: FT-028 CARTILLA ACERO DE REFUERZO (0/1) | AW4: FT-930 REVISIÓN ACERO REFUERZO, FORMALETA Y SPT BASE (0/1) | AX4: Corte y flejado de acero (0/1) | AY4: Acero armado en Sitio de torre (0/1) | AZ4: SPT, varilla, cable, conectores y herramientas (0/1) | BA4: Cantidad de acero solicitado según planilla(kg) | BB4: Cantidad de acero instalado (kg) | BC4: Desviacion del acero (kg) | BD4: Observaciones | BE4: Instalacion de acero en patas A B C y D (0/1) | BF4: Observaciones | BG4: FT-916 PLANILLA NIVELACIÓN DE STUB (0/1) | BH4: Nivelacion de stub patas A B C y D (0/1) | BI4: Encofrado o formaleteado patas A B C y D (0/1) | BJ4: Ingreso de materiales a sitio de torre (Vehiculo, manual, mular o teleférico) | BK4: IT-380 INSTRUCTIVO CIMENTACIÓN EN CONCRETO (0/1) | BL4: FT-056 CONTROL FUNDACIONES DE CONCRETO (0/1) | BM4: Tipo de conctreto (premezclado o hecho en obra) | BN4: Resistencia teorica del concreto en Megapascales | BO4: Cantidad de agua caculada a utilizar, para concreto en sitio (m³) | BP4: Cantidad de agua utilizada, para concreto en sitio (m³) | BQ4: Desviacion de agua para concreto en sitio (m³) | BR4: Observaciones | BS4: Cantidad calculada de arena a utilizar para concreto e sitio (m³) | BT4: Cantidad utilizada de arena para concreto e sitio (m³) | BU4: Desviacion de la cantidad de arena | BV4: Observaciones | BW4: cantidad calculada de grava a utilizar para conocreto en sitio (m³) | BX4: cantidad utilizada de grava para conocreto en sitio (m³) | BY4: Desviacion de la cantidad e grava | BZ4: Observaciones | CA4: Cantidad de cemento estructural calculado para concreto en sitio (kl) | CB4: Cantidad de cemento estructural utilizado para concreto en sitio (kl) | CC4: Desviacion del cemento (kl) | CD4: Observaciones | CE4: Prueba del slump o prueba de acentamiento del concreto (0/1) | CF4: Fecha de vaciado en concreto (D/M/A) | CG4: Fecha de fabricacio de cilindros para prueba de fallo (D/M/A) | CH4: Inspeccion final de nivelacion del stup (0/1) | CI4: Persona encargada de realizar las puntas de diamante en patas ABC yD | CJ4: Desencofrado resane e hidratacion de pedestales patas A B c y D (DMA) | CK4: Tarea de vaciado en conctreto ejecutada (0/1) | CL4: Observaciones | CM4: FT-914 CONTROL DE COMPACTACIÓN (0/1) | CN4: Compactacion con suelo natural (0/1) | CO4: Compactacion con suelo cemento (0/1) | CP4: Compactacion con suelo de prestamo (0/1) | CQ4: Volument de compactacion (m³) | CR4: Compactacion finalizada (0/1) | CS4: Observaciones
B5: E1 | C5: Helicoidal | D5: 1 | E5: A | J5: 1 | AB5: 0.7 | AC5: 1 | AD5: =AC5-AB5 -> 0.3 | AR5: 1 | BA5: 980 | BB5: 980 | BC5: =BA5-BB5 -> 0 | BW5: 3 | BX5: 2.7 | BY5: =BW5-BX5 -> 0.3
E6: B | AB6: 0.9 | AC6: 0.5 | AD6: =AC6-AB6 -> -0.4 | AR6: 1
E7: C | AD7: =AC7-AB7 -> 0 | AR7: 1
E8: D | AD8: =AC8-AB8 -> 0 | AR8: 1
B9: E2 | C9: Zapata | D9: 1 | E9: A | J9: 1 | AD9: =AC9-AB9 -> 0 | AR9: 1
E10: B | AD10: =AC10-AB10 -> 0
E11: C | AD11: =AC11-AB11 -> 0
A12: a | E12: D | Y12: 1 | AD12: =AC12-AB12 -> 0 | AR12: 1 | BE12: 1 | CK12: 1 | CR12: 1 | CT12: =SUMPRODUCT(Y$2:CS$2,Y12:CS12) -> 1
B13: E3 | C13: Helicoidal | D13: 1 | E13: A | J13: 1 | AD13: =AC13-AB13 -> 0
E14: B | AD14: =AC14-AB14 -> 0
E15: C | AD15: =AC15-AB15 -> 0
A16: b | E16: D | Y16: 1 | AD16: =AC16-AB16 -> 0 | AR16: 1 | BE16: 1 | CK16: 1 | CR16: 1 | CT16: =SUMPRODUCT(Y$2:CS$2,Y16:CS16) -> 1
B17: E3 | C17: Helicoidal | D17: 1 | E17: A | AD17: =AC17-AB17 -> 0
E18: B | AD18: =AC18-AB18 -> 0
E19: C | AD19: =AC19-AB19 -> 0
E20: D | AD20: =AC20-AB20 -> 0
B21: E3 | C21: Helicoidal | D21: 1 | E21: A | AD21: =AC21-AB21 -> 0
E22: B | AD22: =AC22-AB22 -> 0
E23: C | AD23: =AC23-AB23 -> 0
E24: D | AD24: =AC24-AB24 -> 0
A25: c | B25: E3 | C25: Helicoidal | D25: 1 | J25: 1 | Y25: 1 | AD25: =AC25-AB25 -> 0 | AR25: 1 | BE25: 1 | CK25: 1 | CR25: 1 | CT25: =SUMPRODUCT(Y$2:CS$2,Y25:CS25) -> 1 | CV25: Ingreso despues del 30 de abril, cambio menor,por desplazamiento por arbol
A26: a | B26: E4 | C26: Helicoidal | D26: 1 | J26: 1 | Y26: 1 | AD26: =AC26-AB26 -> 0 | AR26: 1 | BE26: 1 | CK26: 1 | CR26: 1 | CT26: =SUMPRODUCT(Y$2:CS$2,Y26:CS26) -> 1
A27: b | B27: E5 | C27: Helicoidal | D27: 1 | J27: 1 | Y27: 1 | AD27: =AC27-AB27 -> 0 | AR27: 1 | BE27: 1 | CK27: 1 | CR27: 1 | CT27: =SUMPRODUCT(Y$2:CS$2,Y27:CS27) -> 1
A28: c | B28: E6 | C28: Helicoidal | D28: 1 | J28: 1 | Y28: 1 | AD28: =AC28-AB28 -> 0 | AR28: 1 | BE28: 1 | CK28: 1 | CR28: 1 | CT28: =SUMPRODUCT(Y$2:CS$2,Y28:CS28) -> 1
A29: a | B29: E7 | C29: Helicoidal | D29: 1 | J29: 1 | Y29: 1 | AD29: =AC29-AB29 -> 0 | AR29: 1 | BE29: 1 | CK29: 1 | CR29: 1 | CT29: =SUMPRODUCT(Y$2:CS$2,Y29:CS29) -> 1
A30: c | B30: E8 | C30: Helicoidal | D30: 1 | J30: 1 | Y30: 1 | AD30: =AC30-AB30 -> 0 | AR30: 1 | BE30: 1 | CK30: 1 | CR30: 1 | CT30: =SUMPRODUCT(Y$2:CS$2,Y30:CS30) -> 1
A31: a | B31: E9 | C31: Helicoidal | D31: 1 | J31: 1 | Y31: 1 | AD31: =AC31-AB31 -> 0 | AR31: 1 | BE31: 1 | CK31: 1 | CR31: 1 | CT31: =SUMPRODUCT(Y$2:CS$2,Y31:CS31) -> 1
A32: b | B32: E10 | C32: Helicoidal | D32: 1 | J32: 1 | Y32: 1 | AD32: =AC32-AB32 -> 0 | AR32: 1 | BE32: 1 | CK32: 1 | CR32: 1 | CT32: =SUMPRODUCT(Y$2:CS$2,Y32:CS32) -> 1
A33: c | B33: E11 | C33: zapata | D33: 1 | J33: 1 | Y33: 1 | AD33: =AC33-AB33 -> 0 | AR33: 1 | BE33: 1 | CK33: 1 | CR33: 1 | CT33: =SUMPRODUCT(Y$2:CS$2,Y33:CS33) -> 1
A34: a | B34: E12 | C34: zapata | D34: 1 | J34: 1 | Y34: 1 | AD34: =AC34-AB34 -> 0 | AR34: 1 | BE34: 1 | CK34: 1 | CR34: 1 | CT34: =SUMPRODUCT(Y$2:CS$2,Y34:CS34) -> 1 | CV34: desplazamiento despues del 2 de mayo, solicitud de cambio antel el ICANH
A35: c | B35: E13 | C35: Helicoidal | D35: 1 | J35: 1 | Y35: 1 | AD35: =AC35-AB35 -> 0 | AR35: 1 | BE35: 1 | CK35: 1 | CR35: 1 | CT35: =SUMPRODUCT(Y$2:CS$2,Y35:CS35) -> 1
A36: a | B36: E15 | C36: zapata | D36: 1 | J36: 1 | Y36: 1 | AD36: =AC36-AB36 -> 0 | AR36: 1 | BE36: 1 | CK36: 1 | CR36: 1 | CT36: =SUMPRODUCT(Y$2:CS$2,Y36:CS36) -> 1 | CV36: desplazamiento despues del 30 de mayo, solicitud de cambio antel el ICANH
A37: b | B37: E16 | C37: Helicoidal | D37: 1 | J37: 1 | Y37: 1 | AD37: =AC37-AB37 -> 0 | AR37: 1 | BE37: 1 | CK37: 1 | CR37: 1 | CT37: =SUMPRODUCT(Y$2:CS$2,Y37:CS37) -> 1
A38: c | B38: E20 | C38: Helicoidal | D38: 1 | J38: 1 | Y38: 1 | AD38: =AC38-AB38 -> 0 | AR38: 1 | BE38: 1 | CK38: 1 | CR38: 1 | CT38: =SUMPRODUCT(Y$2:CS$2,Y38:CS38) -> 1
A39: a | B39: E21 | C39: Helicoidal | D39: 1 | J39: 1 | Y39: 1 | AD39: =AC39-AB39 -> 0 | AR39: 1 | BE39: 1 | CK39: 1 | CR39: 1 | CT39: =SUMPRODUCT(Y$2:CS$2,Y39:CS39) -> 1
A40: c | B40: E22 | C40: Helicoidal | D40: 1 | J40: 1 | Y40: 1 | AD40: =AC40-AB40 -> 0 | AR40: 1 | BE40: 1 | CK40: 1 | CR40: 1 | CT40: =SUMPRODUCT(Y$2:CS$2,Y40:CS40) -> 1
...

Sheet OOCC
C1: PROGRAMADAS | M1: CONSTRUIDAS
B2: FECHA | C2: PROGRAMADO X SEMANA | D2: ACUMULADO PROGRAMADO | E2: % AVENCE PROGRAMADO | F2: No DE TORRE | M2: CONSTRUIDO X SEMANA | N2: ACUMULADO CONSTRUIDO | O2: % AVENCE CONSTRUIDO | P2: No TORRE | AB2: PENDIENTE
P3: Torre | Q3: Avance | R3: Torre | S3: Avance | T3: Torre | U3: Avance | V3: Torre | W3: Avance | X3: Torre | Y3: Avance | Z3: Torre | AA3: Avance
B4: 45668 | C4: 0 | D4: =C4 -> 0 | E4: 0 | M4: 0 | N4: =M4 -> 0 | O4: =0 -> 0
B5: 45675 | C5: 2 | D5: =D4+C5 -> 2 | E5: =D5/64 -> 0.03125 | F5: 39 | G5: 42 | M5: =Q5+S5+U5+W5+Y5+AA5 -> 2 | N5: =N4+M5 -> 2 | O5: =N5/64 -> 0.03125 | P5: 42 | Q5: ='CANT OOCC'!CT71 -> 1 | R5: 39 | S5: ='CANT OOCC'!CT54 -> 1
B6: 45682 | C6: 2 | D6: =D5+C6 -> 4 | E6: =D6/64 -> 0.0625 | F6: 41 | M6: =Q6+S6+U6+W6+Y6+AA6 -> 1 | N6: =N5+M6 -> 3 | O6: =N6/64 -> 0.046875 | P6: 41 | Q6: ='CANT OOCC'!CT56 -> 1
B7: 45689 | C7: 1 | D7: =D6+C7 -> 5 | E7: =D7/64 -> 0.078125 | F7: 51 | M7: =Q7+S7+U7+W7+Y7+AA7 -> 1 | N7: =N6+M7 -> 4 | O7: =N7/64 -> 0.0625 | P7: 51 | Q7: ='CANT OOCC'!CT78 -> 1
B8: 45696 | C8: 2 | D8: =D7+C8 -> 7 | E8: =D8/64 -> 0.109375 | F8: 40 | M8: =Q8+S8+U8+W8+Y8+AA8 -> 1 | N8: =N7+M8 -> 5 | O8: =N8/64 -> 0.078125 | P8: 40 | Q8: ='CANT OOCC'!CT55 -> 1 | AE8: Ciment helicoidal
B9: 45703 | C9: 3 | D9: =D8+C9 -> 10 | E9: =D9/64 -> 0.15625 | F9: 47 | G9: 18 | H9: 45 | M9: =Q9+S9+U9+W9+Y9+AA9 -> 3 | N9: =N8+M9 -> 8 | O9: =N9/64 -> 0.125 | P9: 47 | Q9: ='CANT OOCC'!CT74 -> 1 | R9: 18 | S9: ='CANT OOCC'!CT67 -> 1 | T9: 45 | U9: ='CANT OOCC'!CT57 -> 1 | AE9: Ciment zapata
B10: 45710 | C10: 3 | D10: =D9+C10 -> 13 | E10: =D10/64 -> 0.203125 | F10: 14 | G10: 58 | H10: 10 | M10: =Q10+S10+U10+W10+Y10+AA10 -> 4 | N10: =N9+M10 -> 12 | O10: =N10/64 -> 0.1875 | P10: 14 | Q10: ='CANT OOCC'!CT65 -> 1 | R10: 58 | S10: ='CANT OOCC'!CT83 -> 1 | T10: 10 | U10: ='CANT OOCC'!CT32 -> 1 | V10: 48 | W10: ='CANT OOCC'!CT75 -> 1
B11: 45717 | C11: 3 | D11: =D10+C11 -> 16 | E11: =D11/64 -> 0.25 | F11: 1 | G11: 7 | M11: =Q11+S11+U11+W11+Y11+AA11 -> 3 | N11: =N10+M11 -> 15 | O11: =N11/64 -> 0.234375 | P11: 1 | Q11: ='CANT OOCC'!CT12 -> 1 | R11: 43 | S11: ='CANT OOCC'!CT72 -> 1 | T11: 44 | U11: ='CANT OOCC'!CT73 -> 1
B12: 45724 | C12: 3 | D12: =D11+C12 -> 19 | E12: =D12/64 -> 0.296875 | F12: 43 | G12: 4 | H12: 9 | I12: 46 | J12: 44 | M12: =Q12+S12+U12+W12+Y12+AA12 -> 4 | N12: =N11+M12 -> 19 | O12: =N12/64 -> 0.296875 | P12: 9 | Q12: ='CANT OOCC'!CT67 -> 1 | R12: 4 | S12: ='CANT OOCC'!CT26 -> 1 | T12: 16 | U12: ='CANT OOCC'!CT37 -> 1 | V12: 17 | W12: ='CANT OOCC'!CT66 -> 1
B13: 45731 | C13: 4 | D13: =D12+C13 -> 23 | E13: =D13/64 -> 0.359375 | F13: 12 | G13: 32 | H13: 13 | I13: 29 | J13: 59 | K13: 17 | M13: =Q13+S13+U13+W13+Y13+AA13 -> 5 | N13: =N12+M13 -> 24 | O13: =N13/64 -> 0.375 | P13: 5 | Q13: ='CANT OOCC'!CT27 -> 1 | R13: 6 | S13: ='CANT OOCC'!CT28 -> 1 | T13: 7 | U13: ='CANT OOCC'!CT29 -> 1 | V13: 8 | W13: ='CANT OOCC'!CT30 -> 1 | X13: 27 | Y13: ='CANT OOCC'!CT44 -> 1
B14: 45738 | C14: 0 | D14: =D13+C14 -> 23 | E14: =D14/64 -> 0.359375 | F14: 26 | G14: 27 | H14: 52 | I14: 55 | J14: 54 | K14: 19 | L14: 24 | M14: =Q14+S14+U14+W14+Y14+AA14 -> 4 | N14: =N13+M14 -> 28 | O14: =N14/64 -> 0.4375 | P14: 13 | Q14: ='CANT OOCC'!CT35 -> 1 | R14: 26 | S14: ='CANT OOCC'!CT43 -> 1 | T14: 20 | U14: ='CANT OOCC'!CT38 -> 1 | V14: 21 | W14: ='CANT OOCC'!CT39 -> 1
B15: 45745 | C15: 3 | D15: =D14+C15 -> 26 | E15: =D15/64 -> 0.40625 | F15: 49 | G15: 59 | H15: 60 | I15: 61 | J15: 63 | K15: 64 | M15: =Q15+S15+U15+W15+Y15+AA15 -> 5 | N15: =N14+M15 -> 33 | O15: =N15/64 -> 0.515625 | P15: 28 | Q15: ='CANT OOCC'!CT45 -> 1 | R15: 2 | S15: ='CANT OOCC'!CT16 -> 1 | T15: 22 | U15: ='CANT OOCC'!CT40 -> 1 | V15: 35 | W15: ='CANT OOCC'!CT50 -> 1 | X15: 24 | Y15: ='CANT OOCC'!CT42 -> 1
B16: 45752 | C16: 2 | D16: =D15+C16 -> 28 | E16: =D16/64 -> 0.4375 | F16: 65 | G16: 11 | H16: 16 | I16: 53 | M16: =Q16+S16+U16+W16+Y16+AA16 -> 3 | N16: =N15+M16 -> 36 | O16: =N16/64 -> 0.5625 | P16: 36 | Q16: ='CANT OOCC'!CT51 -> 1 | R16: 37 | S16: ='CANT OOCC'!CT52 -> 1 | T16: 38 | U16: ='CANT OOCC'!CT53 -> 1
B17: 45759 | C17: 2 | D17: =D16+C17 -> 30 | E17: =D17/64 -> 0.46875 | F17: 15 | G17: 21 | H17: 20 | I17: 48 | M17: =Q17+S17+U17+W17+Y17+AA17 -> 2 | N17: =N16+M17 -> 38 | O17: =N17/64 -> 0.59375 | P17: 57 | Q17: ='CANT OOCC'!CT60 -> 1 | R17: 62 | S17: ='CANT OOCC'!CT61 -> 1
B18: 45766 | C18: 1 | D18: =D17+C18 -> 31 | E18: =D18/64 -> 0.484375 | F18: 2 | G18: 3 | H18: 28 | I18: 56 | M18: =Q18+S18+U18+W18+Y18+AA18 -> 1 | N18: =N17+M18 -> 39 | O18: =N18/64 -> 0.609375 | P18: 30 | Q18: 1
B19: 45773 | C19: 2 | D19: =D18+C19 -> 33 | E19: =D19/64 -> 0.515625 | F19: 5 | G19: 6 | H19: 33 | M19: =Q19+S19+U19+W19+Y19+AA19 -> 1 | N19: =N18+M19 -> 40 | O19: =N19/64 -> 0.625 | P19: 46 | Q19: 1
B20: 45780 | C20: 3 | D20: =D19+C20 -> 36 | E20: =D20/64 -> 0.5625 | F20: 8 | G20: 23 | H20: 22 | M20: =Q20+S20+U20+W20+Y20+AA20 -> 2 | N20: =N19+M20 -> 42 | O20: =N20/64 -> 0.65625 | P20: 11 | Q20: ='CANT OOCC'!CT33 -> 1 | R20: 32 | S20: ='CANT OOCC'!CT49 -> 1
B21: 45787 | C21: 1 | D21: =D20+C21 -> 37 | E21: =D21/64 -> 0.578125 | F21: 30 | G21: 31 | H21: 34 | M21: =Q21+S21+U21+W21+Y21+AA21 -> 2 | N21: =N20+M21 -> 44 | O21: =N21/64 -> 0.6875 | P21: 63 | Q21: ='CANT OOCC'!CT62 -> 1 | R21: 19 | S21: ='CANT OOCC'!CT68 -> 1
B22: 45794 | C22: 3 | D22: =D21+C22 -> 40 | E22: =D22/64 -> 0.625 | F22: 35 | G22: 36 | H22: 37 | M22: =Q22+S22+U22+W22+Y22+AA22 -> 2 | N22: =N21+M22 -> 46 | O22: =N22/64 -> 0.71875 | P22: 49 | Q22: ='CANT OOCC'!CT76 -> 1 | R22: 3 | S22: ='CANT OOCC'!CT25 -> 1
B23: 45801 | C23: 3 | D23: =D22+C23 -> 43 | E23: =D23/64 -> 0.671875 | F23: 38 | G23: 57 | H23: 62 | M23: =Q23+S23+U23+W23+Y23+AA23 -> 3 | N23: =N22+M23 -> 49 | O23: =N23/64 -> 0.765625 | P23: 12 | Q23: ='CANT OOCC'!CT34 -> 1 | R23: 15 | S23: ='CANT OOCC'!CT36 -> 1 | T23: 65 | U23: ='CANT OOCC'!CT64 -> 1
B24: 45808 | C24: 5 | D24: =D23+C24 -> 48 | E24: =D24/64 -> 0.75 | F24: 23 | G24: 33 | H24: 64 | M24: =Q24+S24+U24+W24+Y24+AA24 -> 3 | N24: =N23+M24 -> 52 | O24: =N24/64 -> 0.8125 | P24: 23 | Q24: ='CANT OOCC'!CT41 -> 1 | R24: 33 | S24: ='CANT OOCC'!CT69 -> 1 | T24: 64 | U24: ='CANT OOCC'!CT63 -> 1
B25: 45815 | C25: 0 | D25: =D24+C25 -> 48 | E25: =D25/64 -> 0.75 | F25: 31 | G25: 29 | M25: =Q25+S25+U25+W25+Y25+AA25 -> 2 | N25: =N24+M25 -> 54 | O25: =N25/64 -> 0.84375 | P25: 31 | Q25: ='CANT OOCC'!CT48 -> 1 | R25: 29 | S25: ='CANT OOCC'!CT46 -> 1
B26: 45822 | C26: 4 | D26: =D25+C26 -> 52 | E26: =D26/64 -> 0.8125 | F26: 52 | G26: 53 | M26: =Q26+S26+U26+W26+Y26+AA26 -> 2 | N26: =N25+M26 -> 56 | O26: =N26/64 -> 0.875 | P26: 52 | Q26: ='CANT OOCC'!CT79 -> 1 | R26: 53 | S26: ='CANT OOCC'!CT80 -> 1
B27: 45829 | C27: 2 | D27: =D26+C27 -> 54 | E27: =D27/64 -> 0.84375 | F27: 34 | G27: 55 | H27: 54 | M27: =Q27+S27+U27+W27+Y27+AA27 -> 3 | N27: =N26+M27 -> 59 | O27: =N27/64 -> 0.921875 | P27: 34 | Q27: 1 | R27: 55 | S27: ='CANT OOCC'!CT82 -> 1 | T27: 54 | U27: ='CANT OOCC'!CT81 -> 1
B28: 45836 | C28: 5 | D28: =D27+C28 -> 59 | E28: =D28/64 -> 0.921875 | F28: 60 | G28: 56 | M28: =Q28+S28+U28+W28+Y28+AA28 -> 2 | N28: =N27+M28 -> 61 | O28: =N28/64 -> 0.953125 | P28: 60 | Q28: ='CANT OOCC'!CT85 -> 1 | R28: 56 | S28: ='CANT OOCC'!CT59 -> 1
B29: 45843 | C29: 2 | D29: =D28+C29 -> 61 | E29: =D29/64 -> 0.953125 | F29: 59 | G29: 61 | H29: 50 | M29: =Q29+S29+U29+W29+Y29+AA29 -> 3 | N29: =N28+M29 -> 64 | O29: =N29/64 -> 1 | P29: 59 | Q29: ='CANT OOCC'!CT84 -> 1 | R29: 61 | S29: ='CANT OOCC'!CT86 -> 1 | T29: 50 | U29: ='CANT OOCC'!CT77 -> 1
B30: 45850 | C30: 3 | D30: =D29+C30 -> 64 | E30: =D30/64 -> 1 | M30: =Q30+S30+U30+W30+Y30+AA30 -> 0 | N30: =N29+M30 -> 64 | O30: =N30/64 -> 1
B31: 45857 | C31: 0 | D31: =D30+C31 -> 64 | E31: =D31/64 -> 1 | M31: =Q31+S31+U31+W31+Y31+AA31 -> 0 | N31: =N30+M31 -> 64 | O31: =N31/64 -> 1
B32: 45864 | C32: 0 | D32: =D31+C32 -> 64 | E32: =D32/64 -> 1 | M32: =Q32+S32+U32+W32+Y32+AA32 -> 0 | N32: =N31+M32 -> 64 | O32: =N32/64 -> 1

Sheet CANT MONTAJE
A1: Estructura | B1: Función | C1: Tipo de torre | D1: Cuerpo | E1: Fecha de Torre recibida en patio (DMA) | F1: Torres recibidas por el patiero a satisfaccion, sin pendientes (0/1) | G1: Observaciones de estructura recibida con pendentes | H1: Encargado de prearmado (Nombre) | I1: Estructura en sitio de torre (0/1) | J1: Fecha de inicio de prearmado (DMA) | K1: Fecha de finalizacion de prearmado (DMA) | L1: Prearamada (0/1) | M1: porcentaje de la actividada de prearmado (%) | N1: Encargado de montaje de torre (Nombre) | O1: Fecha de inicio de montaje (DMA) | P1: Fecha final de montaje (DMA) | Q1: Dias en la tarea de montaje | R1: Torre Montada (0/1) | S1: Observaciones | T1: FT-032 CONTROL DE MONTAJE Y REVISIÓN DE ESTRUCTURA (0/1) | U1: FT-913 CONTROL DE VERTICALIDAD Y TORSIÓN (0/1) | V1: FT-920 RECEPCIÓN MONTAJE DE ESTRUCTURA (0/1) | W1: Revisada (0/1) | X1: Entregada para carga (0/1) | Y1: Peso de diceño de la estructura (kl) | Z1: Peso instalado de estructura (kl) | AA1: Total de estructuras montadas | AB1: Facturadas al dueño del proyecto | AC1: Facturadas por el contratista
I2: 0.1 | L2: 0.2 | R2: 0.45 | W2: 0.25 | AA2: =SUM(E2:X2) -> 1
A3: E1 | B3: =+IF(OR(C3="A",C3="A especial"),"Suspensión","Retención") -> Retención | C3: D | D3: C6 | I3: 1 | L3: 0.8 | R3: 1 | W3: 1 | X3: 1 | AA3: =SUMPRODUCT($I$2:$W$2,I3:W3) -> 0.96 | AB3: 1 | AC3: Cruz
A4: E2 | B4: =+IF(OR(C4="A",C4="A especial"),"Suspensión","Retención") -> Retención | C4: B | D4: C4 | I4: 1 | L4: 1 | R4: 1 | W4: 1 | X4: 0 | AA4: =SUMPRODUCT($I$2:$W$2,I4:W4) -> 1 | AB4: 1 | AC4: Cruz
A5: E3 | B5: =+IF(OR(C5="A",C5="A especial"),"Suspensión","Retención") -> Retención | C5: B | D5: C4 | I5: 1 | L5: 1 | R5: 1 | W5: 1 | X5: 1 | AA5: =SUMPRODUCT($I$2:$W$2,I5:W5) -> 1 | AB5: 1 | AC5: Instelec
A6: E4 | B6: =+IF(OR(C6="A",C6="A especial"),"Suspensión","Retención") -> Retención | C6: D | D6: C4 | I6: 1 | L6: 1 | R6: 1 | W6: 1 | X6: 1 | AA6: =SUMPRODUCT($I$2:$W$2,I6:W6) -> 1 | AB6: 1 | AC6: Higuita
A7: E5 | B7: =+IF(OR(C7="A",C7="A especial"),"Suspensión","Retención") -> Retención | C7: B | D7: C5 | I7: 1 | L7: 1 | R7: 1 | W7: 1 | X7: 1 | AA7: =SUMPRODUCT($I$2:$W$2,I7:W7) -> 1 | AB7: 1 | AC7: Higuita
A8: E6 | B8: =+IF(OR(C8="A",C8="A especial"),"Suspensión","Retención") -> Retención | C8: C | D8: C5 | I8: 1 | L8: 1 | R8: 1 | W8: 1 | X8: 1 | AA8: =SUMPRODUCT($I$2:$W$2,I8:W8) -> 1 | AB8: 1 | AC8: Higuita
A9: E7 | B9: =+IF(OR(C9="A",C9="A especial"),"Suspensión","Retención") -> Retención | C9: B | D9: C5 | I9: 1 | L9: 1 | R9: 1 | W9: 1 | X9: 1 | AA9: =SUMPRODUCT($I$2:$W$2,I9:W9) -> 1 | AB9: 1 | AC9: Higuita
A10: E8 | B10: =+IF(OR(C10="A",C10="A especial"),"Suspensión","Retención") -> Retención | C10: B | D10: C6 | I10: 1 | L10: 1 | R10: 1 | W10: 1 | X10: 1 | AA10: =SUMPRODUCT($I$2:$W$2,I10:W10) -> 1 | AB10: 1 | AC10: Higuita
A11: E9 | B11: =+IF(OR(C11="A",C11="A especial"),"Suspensión","Retención") -> Retención | C11: B | D11: C4 | I11: 1 | L11: 1 | R11: 1 | W11: 1 | X11: 1 | AA11: =SUMPRODUCT($I$2:$W$2,I11:W11) -> 1 | AB11: 1 | AC11: Higuita
A12: E10 | B12: =+IF(OR(C12="A",C12="A especial"),"Suspensión","Retención") -> Retención | C12: B | D12: C3 | I12: 1 | L12: 1 | R12: 1 | W12: 1 | X12: 1 | AA12: =SUMPRODUCT($I$2:$W$2,I12:W12) -> 1 | AB12: 1 | AC12: Higuita
A13: E11 | B13: =+IF(OR(C13="A",C13="A especial"),"Suspensión","Retención") -> Retención | C13: C | D13: C7 | I13: 1 | L13: 1 | R13: 1 | W13: 1 | X13: 1 | AA13: =SUMPRODUCT($I$2:$W$2,I13:W13) -> 1 | AB13: 1 | AC13: Higuita
A14: E12 | B14: =+IF(OR(C14="A",C14="A especial"),"Suspensión","Retención") -> Retención | C14: B | D14: C7 | I14: 1 | L14: 1 | R14: 1 | W14: 1 | X14: 1 | AA14: =SUMPRODUCT($I$2:$W$2,I14:W14) -> 1 | AB14: 1 | AC14: Cruz
... A42: E41 | B42: =+IF(OR(C42="A",C42="A especial"),"Suspensión","Retención") -> Suspensión | C42: A | D42: C4 | I42: 1 | L42: 1 | R42: 1 | W42: 1 | X42: 1 | AA42: =SUMPRODUCT($I$2:$W$2,I42:W42) -> 1 | AB42: 1 | AC42: Cruz
A43: E42 | B43: =+IF(OR(C43="A",C43="A especial"),"Suspensión","Retención") -> Suspensión | C43: A | D43: C3 | I43: 1 | L43: 1 | R43: 1 | W43: 1 | X43: 1 | AA43: =SUMPRODUCT($I$2:$W$2,I43:W43) -> 1 | AB43: 1
A44: E43 | B44: =+IF(OR(C44="A",C44="A especial"),"Suspensión","Retención") -> Retención | C44: D | D44: C5 | I44: 1 | L44: 1 | R44: 1 | W44: 1 | X44: 1 | AA44: =SUMPRODUCT($I$2:$W$2,I44:W44) -> 1 | AB44: 1
A45: E44 | B45: =+IF(OR(C45="A",C45="A especial"),"Suspensión","Retención") -> Retención | C45: D | D45: C5 | I45: 1 | L45: 1 | R45: 1 | W45: 1 | X45: 1 | AA45: =SUMPRODUCT($I$2:$W$2,I45:W45) -> 1 | AB45: 1 | AC45: Higuita
A46: E45 | B46: =+IF(OR(C46="A",C46="A especial"),"Suspensión","Retención") -> Retención | C46: B | D46: C7 | I46: 1 | L46: 1 | R46: 1 | W46: 1 | X46: 1 | AA46: =SUMPRODUCT($I$2:$W$2,I46:W46) -> 1 | AB46: 1 | AC46: Higuita
A47: E46 | B47: =+IF(OR(C47="A",C47="A especial"),"Suspensión","Retención") -> Suspensión | C47: A | D47: C7 | I47: 1 | L47: 1 | R47: 1 | W47: 1 | X47: 1 | AA47: =SUMPRODUCT($I$2:$W$2,I47:W47) -> 1 | AB47: 1
A48: E47 | B48: =+IF(OR(C48="A",C48="A especial"),"Suspensión","Retención") -> Retención | C48: B | D48: C7 | I48: 1 | L48: 1 | R48: 1 | W48: 1 | X48: 1 | AA48: =SUMPRODUCT($I$2:$W$2,I48:W48) -> 1 | AB48: 1 | AC48: Cruz
A49: E48 | B49: =+IF(OR(C49="A",C49="A especial"),"Suspensión","Retención") -> Retención | C49: B | D49: C6 | I49: 1 | L49: 1 | R49: 1 | W49: 1 | X49: 1 | AA49: =SUMPRODUCT($I$2:$W$2,I49:W49) -> 1 | AB49: 1
A50: E49 | B50: =+IF(OR(C50="A",C50="A especial"),"Suspensión","Retención") -> Retención | C50: C | D50: C5 | I50: 1 | L50: 1 | R50: 1 | W50: 1 | X50: 1 | AA50: =SUMPRODUCT($I$2:$W$2,I50:W50) -> 1 | AB50: 1
A51: E50 | B51: =+IF(OR(C51="A",C51="A especial"),"Suspensión","Retención") -> Retención | C51: C | D51: C5 | I51: 1 | L51: 1 | R51: 1 | W51: 1 | X51: 1 | AA51: =SUMPRODUCT($I$2:$W$2,I51:W51) -> 1
A52: E51 | B52: =+IF(OR(C52="A",C52="A especial"),"Suspensión","Retención") -> Suspensión | C52: A | D52: C4 | I52: 1 | L52: 1 | R52: 1 | W52: 1 | X52: 1 | AA52: =SUMPRODUCT($I$2:$W$2,I52:W52) -> 1 | AC52: Higuita
A53: E52 | B53: =+IF(OR(C53="A",C53="A especial"),"Suspensión","Retención") -> Retención | C53: B | D53: C6 | I53: 1 | L53: 1 | R53: 1 | W53: 1 | X53: 1 | AA53: =SUMPRODUCT($I$2:$W$2,I53:W53) -> 1 | AB53: 1 | AC53: Higuita
A54: E53 | B54: =+IF(OR(C54="A",C54="A especial"),"Suspensión","Retención") -> Retención | C54: B | D54: C7 | I54: 1 | L54: 1 | R54: 1 | W54: 1 | X54: 1 | AA54: =SUMPRODUCT($I$2:$W$2,I54:W54) -> 1 | AB54: 1 | AC54: Higuita
A55: E54 | B55: =+IF(OR(C55="A",C55="A especial"),"Suspensión","Retención") -> Retención | C55: B | D55: C4 | I55: 1 | L55: 1 | R55: 1 | W55: 1 | X55: 1 | AA55: =SUMPRODUCT($I$2:$W$2,I55:W55) -> 1 | AC55: Higuita
A56: E55 | B56: =+IF(OR(C56="A",C56="A especial"),"Suspensión","Retención") -> Suspensión | C56: A | D56: C4 | I56: 1 | L56: 1 | R56: 1 | W56: 1 | X56: 1 | AA56: =SUMPRODUCT($I$2:$W$2,I56:W56) -> 1
A57: E56 | B57: =+IF(OR(C57="A",C57="A especial"),"Suspensión","Retención") -> Suspensión | C57: A | D57: C5 | I57: 1 | L57: 1 | R57: 1 | W57: 1 | X57: 1 | AA57: =SUMPRODUCT($I$2:$W$2,I57:W57) -> 1 | AC57: Higuita
A58: E57 | B58: =+IF(OR(C58="A",C58="A especial"),"Suspensión","Retención") -> Retención | C58: B | D58: C3 | I58: 1 | L58: 1 | R58: 1 | W58: 1 | X58: 1 | AA58: =SUMPRODUCT($I$2:$W$2,I58:W58) -> 1 | AC58: Higuita
A59: E58 | B59: =+IF(OR(C59="A",C59="A especial"),"Suspensión","Retención") -> Retención | C59: B | D59: C3 | I59: 1 | L59: 1 | R59: 1 | W59: 1 | X59: 1 | AA59: =SUMPRODUCT($I$2:$W$2,I59:W59) -> 1
A60: E59 | B60: =+IF(OR(C60="A",C60="A especial"),"Suspensión","Retención") -> Retención | C60: B | D60: C2 | I60: 1 | L60: 1 | R60: 1 | W60: 1 | X60: 1 | AA60: =SUMPRODUCT($I$2:$W$2,I60:W60) -> 1
A61: E60 | B61: =+IF(OR(C61="A",C61="A especial"),"Suspensión","Retención") -> Suspensión | C61: A | D61: C7 | I61: 1 | L61: 1 | R61: 1 | W61: 1 | X61: 1 | AA61: =SUMPRODUCT($I$2:$W$2,I61:W61) -> 1 | AC61: Higuita
A62: E61 | B62: =+IF(OR(C62="A",C62="A especial"),"Suspensión","Retención") -> Suspensión | C62: A especial | D62: CU | I62: 1 | L62: 1 | R62: 1 | W62: 1 | X62: 1 | AA62: =SUMPRODUCT($I$2:$W$2,I62:W62) -> 1 | AC62: Higuita
A63: E62 | B63: =+IF(OR(C63="A",C63="A especial"),"Suspensión","Retención") -> Retención | C63: B | D63: C5 | I63: 1 | L63: 1 | R63: 1 | W63: 1 | X63: 1 | AA63: =SUMPRODUCT($I$2:$W$2,I63:W63) -> 1
A64: E63 | B64: =+IF(OR(C64="A",C64="A especial"),"Suspensión","Retención") -> Retención | C64: Especial cruce | D64: CU | I64: 1 | L64: 1 | R64: 1 | W64: 1 | X64: 1 | AA64: =SUMPRODUCT($I$2:$W$2,I64:W64) -> 1
A65: E64 | B65: =+IF(OR(C65="A",C65="A especial"),"Suspensión","Retención") -> Retención | C65: Especial cruce | D65: CU | I65: 1 | L65: 1 | R65: 1 | W65: 1 | X65: 1 | AA65: =SUMPRODUCT($I$2:$W$2,I65:W65) -> 1 | AC65: Cruz
A66: E65 | B66: =+IF(OR(C66="A",C66="A especial"),"Suspensión","Retención") -> Retención | C66: D | D66: C4 | I66: 1 | L66: 1 | R66: 1 | W66: 1 | X66: 1 | AA66: =SUMPRODUCT($I$2:$W$2,I66:W66) -> 1
A67: PORTICO PDO 230 KV | B67: =+IF(OR(C67="A",C67="A especial"),"Suspensión","Retención") -> Retención | C67: Portico puesta de oro 230 kV
...

Sheet MONTAJE
C1: PROGRAMADAS | O1: MONTADAS
B2: FECHA | C2: PROGRAMADO X SEMANA | D2: ACUMULADO PROGRAMADO | E2: % AVENCE PROGRAMADO | F2: No DE TORRE | O2: CONSTRUIDO X SEMANA | P2: ACUMULADO CONSTRUIDO | Q2: % AVENCE CONSTRUIDO | R2: No TORRE | AJ2: PENDIENTE
R3: Torre | S3: Avance | T3: Torre | U3: Avance | V3: Torre | W3: Avance | X3: Torre | Y3: Avance | Z3: Torre | AA3: Avance | AB3: Torre | AC3: Avance | AD3: Torre | AE3: Avance | AF3: Torre | AG3: Avance | AH3: Torre | AI3: Avance
B4: 45801 | C4: 3 | D4: =C4 -> 3 | E4: =D4/64 -> 0.046875 | F4: 1 | G4: 38 | H4: 39 | O4: =S4+U4+W4+Y4+AA4+AC4+AE4+AI4+AG4 -> 2.96 | P4: =D4 -> 3 | Q4: =P4/64 -> 0.046875 | R4: 1 | S4: ='CANT MONTAJE'!AA3 -> 0.96 | T4: 38 | U4: ='CANT MONTAJE'!AA39 -> 1 | V4: 39 | W4: ='CANT MONTAJE'!AA40 -> 1
B5: 45808 | C5: 4 | D5: =D4+C5 -> 7 | E5: =D5/64 -> 0.109375 | F5: 2 | G5: 4 | H5: 14 | I5: 16 | O5: =S5+U5+W5+Y5+AA5+AC5+AE5+AI5+AG5 -> 5 | P5: =P4+O5 -> 8 | Q5: =P5/64 -> 0.125 | R5: 2 | S5: ='CANT MONTAJE'!AA4 -> 1 | T5: 4 | U5: ='CANT MONTAJE'!AA6 -> 1 | V5: 14 | W5: ='CANT MONTAJE'!AA16 -> 1 | X5: 16 | Y5: 1 | Z5: 13 | AA5: 1
B6: 45815 | C6: 4 | D6: =D5+C6 -> 11 | E6: =D6/64 -> 0.171875 | F6: 5 | G6: 8 | H6: 13 | I6: 21 | O6: =S6+U6+W6+Y6+AA6+AC6+AE6+AI6+AG6 -> 5 | P6: =P5+O6 -> 13 | Q6: =P6/64 -> 0.203125 | R6: 5 | S6: ='CANT MONTAJE'!AA7 -> 1 | T6: 8 | U6: ='CANT MONTAJE'!AA10 -> 1 | V6: 21 | W6: ='CANT MONTAJE'!AA23 -> 1 | X6: 9 | Y6: ='CANT MONTAJE'!AA11 -> 1 | Z6: 28 | AA6: ='CANT MONTAJE'!AA29 -> 1
B7: 45822 | C7: 8 | D7: =D6+C7 -> 19 | E7: =D7/64 -> 0.296875 | F7: 3 | G7: 9 | H7: 12 | I7: 17 | J7: 18 | K7: 20 | L7: 23 | M7: 36 | O7: =S7+U7+W7+Y7+AA7+AC7+AE7+AI7+AG7 -> 8 | P7: =P6+O7 -> 21 | Q7: =P7/64 -> 0.328125 | R7: 3 | S7: ='CANT MONTAJE'!AA5 -> 1 | T7: 12 | U7: ='CANT MONTAJE'!AA14 -> 1 | V7: 17 | W7: 1 | X7: 18 | Y7: ='CANT MONTAJE'!AA20 -> 1 | Z7: 20 | AA7: ='CANT MONTAJE'!AA22 -> 1 | AB7: 23 | AC7: ='CANT MONTAJE'!AA25 -> 1 | AD7: 36 | AE7: ='CANT MONTAJE'!AA37 -> 1 | AF7: 32 | AG7: ='CANT MONTAJE'!AA33 -> 1
B8: 45829 | C8: 9 | D8: =D7+C8 -> 28 | E8: =D8/64 -> 0.4375 | F8: 6 | G8: 7 | H8: 10 | I8: 11 | J8: 19 | K8: 24 | L8: 26 | M8: 32 | N8: 41 | O8: =S8+U8+W8+Y8+AA8+AC8+AE8+AI8+AG8 -> 8 | P8: =P7+O8 -> 29 | Q8: =P8/64 -> 0.453125 | R8: 6 | S8: ='CANT MONTAJE'!AA8 -> 1 | T8: 7 | U8: 1 | V8: 10 | W8: ='CANT MONTAJE'!AA12 -> 1 | X8: 11 | Y8: ='CANT MONTAJE'!AA13 -> 1 | Z8: 19 | AA8: ='CANT MONTAJE'!AA21 -> 1 | AB8: 24 | AC8: ='CANT MONTAJE'!AA26 -> 1 | AD8: 26 | AE8: ='CANT MONTAJE'!AA27 -> 1 | AF8: 41 | AG8: 1
B9: 45836 | C9: 8 | D9: =D8+C9 -> 36 | E9: =D9/64 -> 0.5625 | F9: 15 | G9: 27 | H9: 29 | I9: 30 | J9: 31 | K9: 33 | L9: 34 | M9: 37 | O9: =S9+U9+W9+Y9+AA9+AC9+AE9+AI9+AG9 -> 8 | P9: =P8+O9 -> 37 | Q9: =P9/64 -> 0.578125 | R9: 15 | S9: ='CANT MONTAJE'!AA17 -> 1 | T9: 27 | U9: ='CANT MONTAJE'!AA28 -> 1 | V9: 29 | W9: ='CANT MONTAJE'!AA30 -> 1 | X9: 30 | Y9: 1 | Z9: 31 | AA9: ='CANT MONTAJE'!AA32 -> 1 | AB9: 33 | AC9: ='CANT MONTAJE'!AA34 -> 1 | AD9: 34 | AE9: 1 | AF9: 37 | AG9: ='CANT MONTAJE'!AA38 -> 1
B10: 45843 | C10: 9 | D10: =D9+C10 -> 45 | E10: =D10/64 -> 0.703125 | F10: 22 | G10: 35 | H10: 40 | I10: 42 | J10: 43 | K10: 46 | L10: 48 | M10: 57 | N10: 58 | O10: =S10+U10+W10+Y10+AA10+AC10+AE10+AI10+AG10 -> 8 | P10: =P9+O10 -> 45 | Q10: =P10/64 -> 0.703125 | R10: 22 | S10: ='CANT MONTAJE'!AA24 -> 1 | T10: 35 | U10: ='CANT MONTAJE'!AA36 -> 1 | V10: 40 | W10: ='CANT MONTAJE'!AA41 -> 1 | X10: 42 | Y10: ='CANT MONTAJE'!AA43 -> 1 | Z10: 43 | AA10: ='CANT MONTAJE'!AA44 -> 1 | AB10: 46 | AC10: ='CANT MONTAJE'!AA47 -> 1 | AD10: 48 | AE10: ='CANT MONTAJE'!AA49 -> 1 | AF10: 38 | AG10: ='CANT MONTAJE'!AA39 -> 1
B11: 45850 | C11: 7 | D11: =D10+C11 -> 52 | E11: =D11/64 -> 0.8125 | F11: 28 | G11: 44 | H11: 45 | I11: 47 | J11: 49 | K11: 51 | L11: 52 | O11: =S11+U11+W11+Y11+AA11+AC11+AE11+AI11+AG11 -> 8 | P11: =P10+O11 -> 53 | Q11: =P11/64 -> 0.828125 | R11: 44 | S11: ='CANT MONTAJE'!AA45 -> 1 | T11: 45 | U11: ='CANT MONTAJE'!AA46 -> 1 | V11: 47 | W11: ='CANT MONTAJE'!AA48 -> 1 | X11: 49 | Y11: ='CANT MONTAJE'!AA50 -> 1 | Z11: 51 | AA11: ='CANT MONTAJE'!AA52 -> 1 | AB11: 52 | AC11: ='CANT MONTAJE'!AA53 -> 1 | AD11: 53 | AE11: ='CANT MONTAJE'!AA54 -> 1 | AF11: 54 | AG11: ='CANT MONTAJE'!AA55 -> 1
B12: 45857 | C12: 4 | D12: =D11+C12 -> 56 | E12: =D12/64 -> 0.875 | F12: 50 | G12: 56 | H12: 59 | I12: 61 | O12: =S12+U12+W12+Y12+AA12+AC12+AE12+AI12+AG12 -> 8 | P12: =P11+O12 -> 61 | Q12: =P12/64 -> 0.953125 | R12: 56 | S12: ='CANT MONTAJE'!AA57 -> 1 | T12: 62 | U12: ='CANT MONTAJE'!AA63 -> 1 | V12: 55 | W12: ='CANT MONTAJE'!AA56 -> 1 | X12: 57 | Y12: ='CANT MONTAJE'!AA58 -> 1 | Z12: 58 | AA12: ='CANT MONTAJE'!AA59 -> 1 | AB12: 59 | AC12: ='CANT MONTAJE'!AA60 -> 1 | AD12: 60 | AE12: ='CANT MONTAJE'!AA61 -> 1 | AF12: 61 | AG12: ='CANT MONTAJE'!AA62 -> 1
B13: 45864 | C13: 7 | D13: =D12+C13 -> 63 | E13: =D13/64 -> 0.984375 | F13: 53 | G13: 54 | H13: 55 | I13: 60 | J13: 62 | K13: 63 | O13: =S13+U13+W13+Y13+AA13+AC13+AE13+AI13+AG13 -> 3 | P13: =P12+O13 -> 64 | Q13: =P13/64 -> 1 | R13: 63 | S13: ='CANT MONTAJE'!AA64 -> 1 | T13: 64 | U13: ='CANT MONTAJE'!AA65 -> 1 | V13: 65 | W13: ='CANT MONTAJE'!AA66 -> 1
B14: 45871 | C14: 1 | D14: =D13+C14 -> 64 | E14: =D14/64 -> 1 | F14: 64 | O14: =S14+U14+W14+Y14+AA14+AC14+AE14+AI14+AG14 -> 0

Sheet  SPT y Pintura
A1: Sistema de puesta a tierra | Q1: Pintura de patas de torres | W1: Pintado de torres con pintura earonautica
D2: Cable SPT | H2: Polvora | AA2: Franja 1 base gris | AE2: Franja 1 color naranja | AI2: Franja 2 base gris | AM2: Franja 2 color blanco | AQ2: Franja 3 base gris | AU2: Franja 3 color naranja | AY2: Franja 4 base gris | BC2: Franja 4 color blanco | BG2: Franja 5 base gris | BK2: Franja 5 color naranja | BO2: Franja 6 base | BS2: Franja 6 color blanco | BW2: Franja 7 base gris | CA2: Franja 7 color naranja
A3: Estructura | B3: Cuadrilla encargada | C3: Cantidad de excavacion (m) | D3: Cantidad de cable a instalar según planos (m) | E3: Cantidad de cable instalado (m) | F3: Diferencia | G3: Observaciones | H3: Cantidad de tiros por torre de acuerdo a planos SPT (n) | I3: Cantidad de cajas de povora teorica | J3: cantidad de polvora real consumida | K3: Difenencia | L3: observaciones | M3: Avance en porcentaje (%) | N3: FT-068 CONTROL DE COMPENSACIÓN (0/1) | O3: FT-029 LECTURA MEDICIÓN PUESTA A TIERRA (0/1) | P3: Informe de mediciones entregado (0/1) | Q3: FT-912 CONTROL ESPESOR PINTURA PATAS (0/1) | R3: Cuadrilla encargada | S3: Torres pintadas (0/1) | T3: Medicion de espesor de pintura (0/1) | U3: Entrega de pintura de patas (0/1) | V3: Observaciones | W3: FT-933 CONTROL PINTURA AERONAUTICA (0/1) | X3: Quien ejecuta (Nombre) | Y3: Fecha de inicio (DMA) | Z3: Fecha final (DMA) | AA3: Franja 1 base gris porcentaje de avance (%) | AB3: Cantidad de pintura base proyectada a consumir (Gal) | AC3: Cantidad de pintura base consumida (Gal) | AD3: Observaciones | AE3: Franja 1 color naranja, porcentaje de avance (%) | AF3: Cantdiad de pintura naranja Proyectada a consumir (Gal) | AG3: Cantidad de pintura naranaja consumida (Gal) | AH3: Observaciones | AI3: Franja 2 base gris, Porcentaje de avance (%) | AJ3: Cantidad de pintura base proyectada a consumir (Gal) | AK3: Cantidad de pintura base consumida (Gal) | AL3: Observaciones | AM3: Franja 2 color blanco, porcentaje de avance (%) | AN3: Cantdiad de pintura blanca Proyectada a consumir (Gal) | AO3: Cantidad de pintura blanca consumida (Gal) | AP3: Observaciones | AQ3: Franja 3 base gris, porcentaje de avance (%) | AR3: Cantidad de pintura base proyectada a consumir (Gal) | AS3: Cantidad de pintura base consumida (Gal) | AT3: Observaciones | AU3: Frnaja 3 color naranja, porcentaje de avance (%) | AV3: Cantdiad de pintura naranja Proyectada a consumir (Gal) | AW3: Cantidad de pintura naranaja consumida (Gal) | AX3: Observaciones | AY3: Franja 4 base gris, porcentaje de avance (%) | AZ3: Cantidad de pintura base proyectada a consumir (Gal) | BA3: Cantidad de pintura base consumida (Gal) | BB3: Observaciones | BC3: Franja 4 color blanco, porcentaje de avance (%) | BD3: Cantdiad de pintura blanca Proyectada a consumir (Gal) | BE3: Cantidad de pintura blanca consumida (Gal) | BF3: Observaciones | BG3: Franja 5 base gris, porcentaje de avance (%) | BH3: Cantidad de pintura base proyectada a consumir (Gal) | BI3: Cantidad de pintura base consumida (Gal) | BJ3: Observaciones | BK3: Franja 5 color naranja, porcentaje dea avance (%) | BL3: Cantdiad de pintura naranja Proyectada a consumir (Gal) | BM3: Cantidad de pintura naranaja consumida (Gal) | BN3: Observaciones | BO3: Franja 6 base, porcentaje de avance (%) | BP3: Cantidad de pintura base proyectada a consumir (Gal) | BQ3: Cantidad de pintura base consumida (Gal) | BR3: Observaciones | BS3: Franja 6 color blanco, porcentaje de avance (%) | BT3: Cantdiad de pintura blanca Proyectada a consumir (Gal) | BU3: Cantidad de pintura blanca consumida (Gal) | BV3: Observaciones | BW3: Franja 7 base gris, porcentaje de avance (%) | BX3: Cantidad de pintura base proyectada a consumir (Gal) | BY3: Cantidad de pintura base consumida (Gal) | BZ3: Observaciones | CA3: Franja 7 color naranja, Porcentaje de avance (%) | CB3: Cantdiad de pintura naranja Proyectada a consumir (Gal) | CC3: Cantidad de pintura naranaja consumida (Gal) | CD3: Observaciones | CE3: Revicion de espesor en micras (0/1) | CF3: Entrega de pintura (0/1)
A5: E1 | B5: Cruz | M5: 1
A6: E2 | B6: wilson | M6: 1
A7: E3 | B7: Angel | M7: 1
A8: E4 | B8: Mec | M8: 1
A9: E5 | B9: Cruz | M9: 1
A10: E6 | B10: Cruz | M10: 1
A11: E7 | B11: Cruz | M11: 1
A12: E8 | B12: Cruz | M12: 1
A13: E9 | B13: Mec | M13: 1
A14: E10 | B14: Mec | M14: 1
A15: E11 | B15: Mec | M15: 1
A16: E12 | B16: Cruz | M16: 1
... A57: E54 | B57: Mec | M57: 1
A58: 55 | B58: Angel | M58: 1
A59: E56 | B59: Toro | M59: 1
A60: E57 | B60: Angel | M60: 1
A61: E58 | B61: Angel | M61: 1
A62: E59 | B62: Julio | M62: 1
A63: E60 | B63: Toro | M63: 1
A64: E61 | B64: Angel | M64: 1
A65: E62 | B65: Angel | M65: 1
A66: E63 | B66: Angel | M66: 1
A67: E64 | B67: Cruz | M67: 1
A68: E65 | B68: Cruz | M68: 1
M69: 64
A70: Total
M71: 63

Sheet CANT TENDIDO
A1: Estructura | B1: Función | C1: Tipo de torre | D1: Cuerpo | E1: Vestida | F1: Riega de manila | G1: Riega de guaya Conductor | H1: tendido de conductor | I1: Grapado o amarre | J1: Accesorios y puentes | K1: Balizas ó desviadores de vuelo | L1: Plscas de señalizac | M1: Facturadas HMV | N1: Realizó | O1: vestida de fibra | P1: Reiga de manila para fibra | Q1: Riega de guaya OPGW | R1: Tendido de OPGW | S1: grapado y amarre de fibra | T1: Empalmes OPGW
F2: 0.1 | G2: 0.3 | H2: 0.3 | I2: 0.1 | J2: 0.1 | K2: 0.1 | P2: 0.1 | Q2: 0.2 | R2: 0.4 | S2: 0.2 | T2: 0.1
A3: PORTICO SAN FELIPE 230 KV | B3: =+IF(OR(C3="A",C3="A especial"),"Suspensión","Retención") -> Retención | C3: Portico San Felipe 230 kV | E3: 1 | F3: 1 | G3: 1 | H3: 1 | I3: 1 | J3: 1 | O3: 1 | P3: 1 | Q3: 1 | R3: 1 | S3: 1 | T3: 1
A4: E1 | B4: =+IF(OR(C4="A",C4="A especial"),"Suspensión","Retención") -> Retención | C4: D | D4: C6 | E4: 1 | F4: 1 | G4: 1 | H4: 1 | I4: 1 | J4: 1 | K4: 1 | L4: =SUMPRODUCT($E$3:$J$3,E4:J4) -> 6 | O4: 1 | P4: 1 | Q4: 1 | R4: 1 | S4: 1
A5: E2 | B5: =+IF(OR(C5="A",C5="A especial"),"Suspensión","Retención") -> Retención | C5: B | D5: C4 | E5: 1 | F5: 1 | G5: 1 | H5: 1 | I5: 1 | J5: 1 | K5: 1 | L5: =SUMPRODUCT($E$3:$J$3,E5:J5) -> 6 | N5: Construmext | O5: 1 | P5: 1 | Q5: 1 | R5: 1 | S5: 1
A6: E3 | B6: =+IF(OR(C6="A",C6="A especial"),"Suspensión","Retención") -> Retención | C6: B | D6: C4 | E6: 1 | F6: 1 | G6: 1 | H6: 1 | I6: 1 | J6: 1 | K6: 1 | L6: 3 | O6: 1 | P6: 1 | Q6: 1 | R6: 1 | S6: 1
A7: E4 | B7: =+IF(OR(C7="A",C7="A especial"),"Suspensión","Retención") -> Retención | C7: D | D7: C4 | E7: 1 | F7: 1 | G7: 1 | H7: 1 | I7: 1 | J7: 1 | L7: 3 | O7: 1 | P7: 1 | Q7: 1 | R7: 1 | S7: 1
A8: E5 | B8: =+IF(OR(C8="A",C8="A especial"),"Suspensión","Retención") -> Retención | C8: B | D8: C5 | E8: 1 | F8: 1 | G8: 1 | H8: 1 | I8: 1 | J8: 1 | L8: 3 | N8: Construmext | O8: 1 | P8: 1 | Q8: 1 | R8: 1 | S8: 1
A9: E6 | B9: =+IF(OR(C9="A",C9="A especial"),"Suspensión","Retención") -> Retención | C9: C | D9: C5 | E9: 1 | F9: 1 | G9: 1 | H9: 1 | I9: 1 | J9: 1 | L9: 3 | N9: Construmext | O9: 1 | P9: 1 | Q9: 1 | R9: 1 | S9: 1
A10: E7 | B10: =+IF(OR(C10="A",C10="A especial"),"Suspensión","Retención") -> Retención | C10: B | D10: C5 | E10: 1 | F10: 1 | G10: 1 | H10: 1 | I10: 1 | J10: 1 | K10: 1 | L10: 3 | N10: Construmext | O10: 1 | P10: 1 | Q10: 1 | R10: 1 | S10: 1
A11: E8 | B11: =+IF(OR(C11="A",C11="A especial"),"Suspensión","Retención") -> Retención | C11: B | D11: C6 | E11: 1 | F11: 1 | G11: 1 | H11: 1 | I11: 1 | J11: 1 | K11: 1 | L11: 3 | N11: Construmext | O11: 1 | P11: 1 | Q11: 1 | R11: 1 | S11: 1
A12: E9 | B12: =+IF(OR(C12="A",C12="A especial"),"Suspensión","Retención") -> Retención | C12: B | D12: C4 | E12: 1 | F12: 1 | G12: 1 | H12: 1 | I12: 1 | J12: 1 | K12: 1 | L12: 3 | N12: Construmext | O12: 1 | P12: 1 | Q12: 1 | R12: 1 | S12: 1
A13: E10 | B13: =+IF(OR(C13="A",C13="A especial"),"Suspensión","Retención") -> Retención | C13: B | D13: C3 | E13: 1 | F13: 1 | G13: 1 | H13: 1 | I13: 1 | J13: 1 | L13: 3 | N13: Construmext | O13: 1 | P13: 1 | Q13: 1 | R13: 1 | S13: 1 | T13: 1
A14: E11 | B14: =+IF(OR(C14="A",C14="A especial"),"Suspensión","Retención") -> Retención | C14: C | D14: C7 | E14: 1 | F14: 1 | G14: 1 | H14: 1 | I14: 1 | J14: 1 | K14: 1 | L14: 3 | N14: Construmext | O14: 1 | P14: 1 | Q14: 1 | R14: 1 | S14: 1
A15: E12 | B15: =+IF(OR(C15="A",C15="A especial"),"Suspensión","Retención") -> Retención | C15: B | D15: C7 | E15: 1 | F15: 1 | G15: 1 | H15: 1 | I15: 1 | J15: 1 | K15: 1 | L15: 3 | N15: Construmext | O15: 1 | P15: 1 | Q15: 1 | R15: 1 | S15: 1
A16: E13 | B16: =+IF(OR(C16="A",C16="A especial"),"Suspensión","Retención") -> Retención | C16: C | D16: C2 | E16: 1 | F16: 1 | G16: 1 | H16: 1 | I16: 1 | J16: 1 | K16: 1 | L16: 3 | N16: Construmext | O16: 1 | P16: 1 | Q16: 1 | R16: 1 | S16: 1
A17: E14 | B17: =+IF(OR(C17="A",C17="A especial"),"Suspensión","Retención") -> Retención | C17: B | D17: C4 | E17: 1 | F17: 1 | G17: 1 | H17: 1 | I17: 1 | J17: 1 | L17: 3 | N17: Construmext | O17: 1 | P17: 1 | Q17: 1 | R17: 1 | S17: 1
A18: E15 | B18: =+IF(OR(C18="A",C18="A especial"),"Suspensión","Retención") -> Suspensión | C18: A | D18: C7 | E18: 1 | F18: 1 | G18: 1 | H18: 1 | I18: 1 | J18: 1 | K18: 1 | L18: 3 | N18: Construmext | O18: 1 | P18: 1 | Q18: 1 | R18: 1 | S18: 1 | W18: 1
A19: E16 | B19: =+IF(OR(C19="A",C19="A especial"),"Suspensión","Retención") -> Suspensión | C19: A | D19: C5 | E19: 1 | F19: 1 | G19: 1 | H19: 1 | I19: 1 | J19: 1 | K19: 1 | L19: 3 | N19: Construmext | O19: 1 | P19: 1 | Q19: 1 | R19: 1 | S19: 1 | W19: =1/1.02 -> 0.98039216
A20: E17 | B20: =+IF(OR(C20="A",C20="A especial"),"Suspensión","Retención") -> Suspensión | C20: A | D20: C5 | E20: 1 | F20: 1 | G20: 1 | H20: 1 | I20: 1 | J20: 1 | K20: 1 | L20: 3 | N20: Construmext | O20: 1 | P20: 1 | Q20: 1 | R20: 1 | S20: 1
A21: E18 | B21: =+IF(OR(C21="A",C21="A especial"),"Suspensión","Retención") -> Retención | C21: B | D21: C2 | E21: 1 | F21: 1 | G21: 1 | H21: 1 | I21: 1 | J21: 1 | K21: 1 | L21: 3 | N21: Construmext | O21: 1 | P21: 1 | Q21: 1 | R21: 1 | S21: 1
A22: E19 | B22: =+IF(OR(C22="A",C22="A especial"),"Suspensión","Retención") -> Suspensión | C22: A | D22: C6 | E22: 1 | F22: 1 | G22: 1 | H22: 1 | I22: 1 | J22: 1 | K22: 1 | L22: 3 | N22: Construmext | O22: 1 | P22: 1 | Q22: 1 | R22: 1 | S22: 1 | T22: 1
A23: E20 | B23: =+IF(OR(C23="A",C23="A especial"),"Suspensión","Retención") -> Suspensión | C23: A | D23: C7 | E23: 1 | F23: 1 | G23: 1 | H23: 1 | I23: 1 | J23: 1 | K23: 1 | L23: 3 | N23: Construmext | O23: 1 | P23: 1 | Q23: 1 | R23: 1 | S23: 1
A24: E21 | B24: =+IF(OR(C24="A",C24="A especial"),"Suspensión","Retención") -> Retención | C24: B | D24: C2 | E24: 1 | F24: 1 | G24: 1 | H24: 1 | I24: 1 | J24: 1 | K24: 1 | L24: 3 | N24: Construmext | O24: 1 | P24: 1 | Q24: 1 | R24: 1 | S24: 1
A25: E22 | B25: =+IF(OR(C25="A",C25="A especial"),"Suspensión","Retención") -> Retención | C25: C | D25: C7 | E25: 1 | F25: 1 | G25: 1 | H25: 1 | I25: 1 | J25: 1 | K25: 1 | L25: 3 | O25: 1 | P25: 1 | Q25: 1 | R25: 1 | S25: 1
A26: E23 | B26: =+IF(OR(C26="A",C26="A especial"),"Suspensión","Retención") -> Retención | C26: B | D26: C7 | E26: 1 | F26: 1 | G26: 1 | H26: 1 | I26: 1 | J26: 1 | K26: 1 | L26: 3 | N26: Construmext | O26: 1 | P26: 1 | Q26: 1 | R26: 1 | S26: 1
A27: E24 | B27: =+IF(OR(C27="A",C27="A especial"),"Suspensión","Retención") -> Retención | C27: B | D27: C7 | E27: 1 | F27: 1 | G27: 1 | H27: 1 | I27: 1 | J27: 1 | K27: 1 | L27: 3 | N27: Construmext | O27: 1 | P27: 1 | Q27: 1 | R27: 1 | S27: 1
A28: E26 | B28: =+IF(OR(C28="A",C28="A especial"),"Suspensión","Retención") -> Retención | C28: B | D28: C3 | E28: 1 | F28: 1 | G28: 1 | H28: 1 | I28: 1 | J28: 1 | L28: 3 | N28: Construmext | O28: 1 | P28: 1 | Q28: 1 | R28: 1 | S28: 1
A30: E27 | B30: =+IF(OR(C30="A",C30="A especial"),"Suspensión","Retención") -> Suspensión | C30: A | D30: C6 | E30: 1 | F30: 1 | G30: 1 | H30: 1 | I30: 1 | J30: 1 | L30: 3 | O30: 1 | P30: 1 | Q30: 1 | R30: 1 | S30: 1
A31: E28 | B31: =+IF(OR(C31="A",C31="A especial"),"Suspensión","Retención") -> Retención | C31: B | D31: C5 | E31: 1 | F31: 1 | G31: 1 | H31: 1 | I31: 1 | J31: 1 | L31: 3 | O31: 1 | P31: 1 | Q31: 1 | R31: 1 | S31: 1 | T31: 1
A32: E29 | B32: =+IF(OR(C32="A",C32="A especial"),"Suspensión","Retención") -> Retención | C32: C | D32: C4 | E32: 1 | F32: 1 | G32: 1 | H32: 1 | I32: 1 | J32: 1 | L32: 3 | O32: 1 | P32: 1 | Q32: 1 | R32: 1 | S32: 1
A33: E30 | B33: =+IF(OR(C33="A",C33="A especial"),"Suspensión","Retención") -> Retención | C33: B | D33: C7 | E33: 1 | F33: 1 | G33: 1 | H33: 1 | I33: 1 | J33: 1 | L33: 3 | O33: 1 | P33: 1 | Q33: 1 | R33: 1 | S33: 1
A34: E31 | B34: =+IF(OR(C34="A",C34="A especial"),"Suspensión","Retención") -> Suspensión | C34: A | D34: C7 | E34: 1 | F34: 1 | G34: 1 | H34: 1 | I34: 1 | J34: 1 | L34: 3 | O34: 1 | P34: 1 | Q34: 1 | R34: 1 | S34: 1
A35: E32 | B35: =+IF(OR(C35="A",C35="A especial"),"Suspensión","Retención") -> Suspensión | C35: A | D35: C6 | E35: 1 | F35: 1 | G35: 1 | H35: 1 | I35: 1 | J35: 1 | L35: 3 | O35: 1 | P35: 1 | Q35: 1 | R35: 1 | S35: 1
A36: E33 | B36: =+IF(OR(C36="A",C36="A especial"),"Suspensión","Retención") -> Retención | C36: B | D36: C6 | E36: 1 | F36: 1 | G36: 1 | H36: 1 | I36: 1 | J36: 1 | L36: 3 | O36: 1 | P36: 1 | Q36: 1 | R36: 1 | S36: 1
A37: E34 | B37: =+IF(OR(C37="A",C37="A especial"),"Suspensión","Retención") -> Retención | C37: B | D37: C4 | E37: 1 | F37: 1 | G37: 1 | H37: 1 | I37: 1 | J37: 1 | L37: 3 | O37: 1 | P37: 1 | Q37: 1 | R37: 1 | S37: 1
A38: E35 | B38: =+IF(OR(C38="A",C38="A especial"),"Suspensión","Retención") -> Retención | C38: B | D38: C4 | E38: 1 | F38: 1 | G38: 1 | H38: 1 | I38: 1 | J38: 1 | L38: 3 | O38: 1 | P38: 1 | Q38: 1 | R38: 1 | S38: 1
A39: E36 | B39: =+IF(OR(C39="A",C39="A especial"),"Suspensión","Retención") -> Retención | C39: D | D39: C2 | E39: 1 | F39: 1 | G39: 1 | H39: 1 | I39: 1 | J39: 1 | L39: 3 | O39: 1 | P39: 1 | Q39: 1 | R39: 1 | S39: 1 | T39: 1
A40: E37 | B40: =+IF(OR(C40="A",C40="A especial"),"Suspensión","Retención") -> Retención | C40: C | D40: C2 | E40: 1 | F40: 1 | G40: 1 | H40: 1 | I40: 1 | J40: 1 | L40: 3 | O40: 1 | P40: 1 | Q40: 1 | R40: 1 | S40: 1
A41: E38 | B41: =+IF(OR(C41="A",C41="A especial"),"Suspensión","Retención") -> Suspensión | C41: A | D41: C3 | E41: 1 | F41: 1 | G41: 1 | H41: 1 | I41: 1 | L41: 3 | O41: 1 | P41: 1 | Q41: 1 | R41: 1 | S41: 1
...

Sheet Trinchos y cunetas
A1: OBRAS DE PROTECCION | F1: Materiales
A2: Torre | B2: Medida de manejo | C2: Metros lineales de trinchos | D2: Metros lineales de cunetas | E2: Nota | F2: Tubo metálico 3mx3" recubriemiento en caliente de zinc (50micras) | G2: Malla eslabonada galvanizada en caliente doble inmersión (calibre 10) tejida 50x50mm | H2: Alambre galvanizado (kilo) | I2: Geotexti (metros) | J2: cemento de uso general para trinchos (bulto 50K) | K2: arena (cuñetes) | L2: gava (cuñetes) | M2: Cuadrilla | N2: Avance %
A3: T004 | B3: Cuneta | D3: 15 | M3: Mec | N3: 1
A4: T019 | B4: Cuneta | D4: 14 | M4: Angel | N4: 1
A5: T033 | B5: Cuneta y trinchos | C5: 27.5 | D5: 10 | E5: Revejetalizar, agrotextil y semilla | F5: 33 | G5: 30 | H5: 50 | I5: 30 | J5: 47.52 | K5: 142.56 | L5: 190.08 | M5: Julio Morales | N5: 1
A6: T049 | D6: 20 | M6: Mec | N6: 1
A7: T050 | C7: 10 | D7: 21 | E7: Revejetalizar, agrotextil y semilla | F7: 12 | G7: 11 | H7: 10 | I7: 12 | J7: 17.28 | K7: 51.84 | L7: 69.12 | M7: Toro | N7: 1
A8: T052 | D8: 20 | M8: Mec | N8: 1
A9: T054 | B9: Cuneta y trinchos | C9: 10 | D9: 25 | F9: 12 | G9: 11 | H9: 10 | I9: 12 | J9: 17.28 | K9: 51.84 | L9: 69.12 | M9: Mec | N9: 1
A10: T055 | B10: Cuneta y trinchos | C10: 5 | D10: 10 | F10: 5 | G10: 6 | H10: 2 | I10: 7 | J10: 7.2 | K10: 21.6 | L10: 28.8 | M10: Angel | N10: 1
A11: T056 | B11: Cuneta y trinchos | C11: 10 | D11: 50 | F11: 12 | G11: 11 | H11: 10 | I11: 12 | J11: 17.28 | K11: 51.84 | L11: 69.12 | M11: Toro | N11: 1
A12: T060 | B12: Cuneta y trinchos | C12: 11 | D12: 23 | E12: Revejetalizar, agrotextil y semilla | F12: 13 | G12: 12 | H12: 10 | I12: 13 | J12: 18.72 | K12: 56.16 | L12: 74.88 | M12: Angel | N12: 1
A13: T34 | M13: Julio Morales | N13: 1
A14: T23 | B14: Cuneta | C14: 30 | M14: Angel | N14: 1
A15: T53 | I15: 86 | M15: Julio Morales | N15: 1
A16: Total | F16: 87 | G16: 81 | H16: 92 | I16: 43 | J16: 126 | K16: 378 | L16: 504
